File: Модуль 4/5 OUT-OF-PLANE 30K 8T.DAT
[Header]
; VSM Data File (default extension .dat)
; Copyright (c) 2003-2013, Quantum Design, Inc. All rights reserved.
TITLE,
FILEOPENTIME,40031144.98,04/08/2024,6:48 pm
BYAPP,VSM,2.0,2.0
INFO,PPMS VSM Option Release 1.4.10 Build 1,APPNAME
INFO,Quantum Design Linear Motor Servo Controller,MOTOR_MODULE_NAME
INFO,3101-100 E4,MOTOR_HW_VERSION
INFO,MMC433,MOTOR_SERIAL_NUMBER
INFO,SRV No X-over 01.01.11,MOTOR_SOFTWARE_VERSION
INFO,Quantum Design VSM Detection Module,VSM_MODULE_NAME
INFO,3101-150 E1,VSM_HW_VERSION
INFO,354,VSM_SERIAL_NUMBER
INFO,VSM No X-over 01.02.05 May 20 2008 13:51:47,VSM_SOFTWARE_VERSION
INFO,339,PREAMP_SERIAL_NUMBER
INFO,Quantum Design VSM Oven,OVEN_MODULE_NAME
INFO,3101-200 D0,OVEN_HW_VERSION
INFO,OVN180,OVEN_SERIAL_NUMBER
INFO,01.01.00,OVEN_SOFTWARE_VERSION
INFO,LB602,COIL_SERIAL_NUMBER
INFO,0,MOMENT_UNITS
INFO,Ni5e11 out-of-plane,SAMPLE_MATERIAL
INFO,,SAMPLE_COMMENT
INFO,,SAMPLE_MASS
INFO,,SAMPLE_VOLUME
INFO,,SAMPLE_MOLECULAR_WEIGHT
INFO,,SAMPLE_SIZE
INFO,,SAMPLE_SHAPE
DATATYPE,COMMENT,1
DATATYPE,TIME,2
STARTUPAXIS,X,2
STARTUPAXIS,Y1,5
[Data]
Comment,Time Stamp (sec),Temperature (K),Magnetic Field (Oe),Moment (emu),M. Std. Err. (emu),Transport Action,Averaging Time (sec),Frequency (Hz),Peak Amplitude (mm),Center Position (mm),Coil Signal' (mV),Coil Signal" (mV),Range (mV),M. Quad. Signal (emu),M. Raw' (emu),M. Raw" (emu),Min. Temperature (K),Max. Temperature (K),Min. Field (Oe),Max. Field (Oe),Mass (grams),Motor Lag (deg),Pressure (Torr),VSM Status (code),Motor Status (code),Measure Status (code),Measure Count,PPMS Status (code),System Temp. (K),System Field (Oe),Sample Position (deg),Bridge 1 Resistance (ohms),Bridge 1 Excitation (에),Bridge 2 Resistance (ohms),Bridge 2 Excitation (에),Bridge 3 Resistance (ohms),Bridge 3 Excitation (에),Bridge 4 Resistance (ohms),Bridge 4 Excitation (에),Signal 1 Vin (V),Signal 2 Vin (V),Digital Inputs (code),Drive 1 Iout (mA),Drive 1 Ipower (W),Drive 2 Iout (mA),Drive 2 Ipower (W),Pressure (),Map 20 (),Map 21 (),Map 22 (),Map 23 (),Map 24 (),Map 25 (),Map 26 (),Map 27 (),Map 28 (),Map 29 ()
sample offset = 35 mm,40031163.71,29.9946575,0.148519910871983,0.553103838151518,8.43467703824278E-5,1,0.999253354069792,40.0298881530762,2.00207848508307,11.5799997001886,2.8049093207243,0.634031934320852,25,0.00876874865003947,0.520896112347099,0.024847352826756,29.9946575,29.9946575,0.140703067183495,0.156336754560471,48.1170516438512,18.4190129360542,7.799073,0,0,0,40,4929,30.059,0.148519910871983,,,,,,,,,,,,,0,,,,1.068772,,,,,,29.9946575,,,,
,40031240.97,29.9943218,4090.58422851562,-0.695708832240444,0.000111078645651314,1,0.999253354069792,40.0298881530762,2.00223376006236,11.5900002419949,-3.53281885160846,-0.799847314932362,25,-0.010567534749872,-0.656065856201777,-0.0315210581367065,29.9943218,29.9943218,4080.0341796875,4101.13427734375,48.7564237725821,18.4211053150882,7.799073,0,0,0,40,4961,30.0552,4090.58422851562,,,,,,,,,,,,,0,,,,1.068772,,,,,,29.9943218,,,,
,40031297.52,29.99515915,8040.19067382813,-0.555949994389221,0.000131426405220721,1,0.999253354069792,40.0298881530762,2.00207861858601,11.5799997001886,-2.82730520020135,-0.642038869347933,25,-0.00816196910016915,-0.525147968331927,-0.0255715904506287,29.9949818,29.9953365,8029.708984375,8050.67236328125,49.3160697923514,18.4233104425929,7.799073,0,0,0,40,4961,30.058,8040.19067382813,,,,,,,,,,,,,0,,,,1.0903405,,,,,,29.99515915,,,,
,40031352.995,29.9984264,11924.451171875,-0.451589676731559,9.18356160682041E-5,1,0.999253354069792,40.0298881530762,2.00244145509484,11.5799997001886,-2.30095712243569,-0.523925490972119,25,-0.00638576471421587,-0.427352269759553,-0.0210595482880871,29.9984264,29.9984264,11921.0029296875,11927.8994140625,48.9573023020244,18.4314540584256,7.059639,0,0,0,40,4961,30.0592,11924.451171875,,,,,,,,,,,,,0,,,,1.0903405,,,,,,29.9984264,,,,
,40031408.965,29.9976692,15843.3520507813,-0.386684617659276,6.87497630011247E-5,1,0.999253354069792,40.0298881530762,2.00214785962582,11.5900002419949,-1.973532912875,-0.451196310577086,25,-0.00539697071243254,-0.366650317994865,-0.0183912775072884,29.9976692,29.9976692,15832.7958984375,15853.908203125,48.8353682530244,18.4282759723878,7.799073,0,0,0,40,4961,30.057,15843.3520507813,,,,,,,,,,,,,0,,,,1.068772,,,,,,29.9976692,,,,
,40031465.175,29.9991055,19775.9091796875,-0.342977392959384,5.93319359740479E-5,1,0.999253354069792,40.0298881530762,2.00230529812882,11.5799997001886,-1.75403391964625,-0.40217136372512,25,-0.0046709490889753,-0.325882468431213,-0.0165512508350499,29.9991055,29.9991055,19765.501953125,19786.31640625,48.3476320570243,18.429408597301,7.059639,0,0,0,40,4961,30.06005,19775.9091796875,,,,,,,,,,,,,0,,,,1.0581483,,,,,,29.9991055,,,,
,40031521.095,29.998724,23691.0625,-0.310404083098486,6.74141561185086E-5,1,0.999253354069792,40.0298881530762,2.00218390076382,11.5799997001886,-1.59052751120734,-0.36581041853431,25,-0.00417593234091476,-0.29555758848406,-0.0152107816792691,29.998724,29.998724,23684.056640625,23698.068359375,49.1573992029475,18.4276806115886,7.799073,0,0,0,40,4961,30.0597,23691.0625,,,,,,,,,,,,,0,,,,1.0903405,,,,,,29.998724,,,,
,40031579.1,29.9999123,27746.423828125,-0.284141599024401,6.03950746019653E-5,1,0.999253354069792,40.0298881530762,2.00249170207478,11.5799997001886,-1.45928732919324,-0.336439039134463,25,-0.00376469469219374,-0.2711550347513,-0.0140987481776003,29.9999123,29.9999123,27735.88671875,27756.9609375,49.0815812365821,18.4357998414398,7.059639,0,0,0,40,4961,30.0577,27746.423828125,,,,,,,,,,,,,0,,,,1.0581483,,,,,,29.9999123,,,,
,40031633.465,29.8231869,31552.7294921875,-0.265361705190968,6.42333677879773E-5,1,0.999253354069792,40.0298881530762,2.00241361276968,11.5799997001886,-1.36572851625774,-0.315576777935993,25,-0.00348928533776982,-0.253802506336538,-0.0133217142893548,29.8231869,29.8231869,31542.33203125,31563.126953125,48.5063026464282,18.4366147916916,7.799073,0,0,0,40,4965,30.2831,31552.7294921875,,,,,,,,,,,,,0,,,,1.0742444,,,,,,29.8231869,,,,
,40031684.58,30.0276728,35128.830078125,-0.247709059577284,6.85294999397534E-5,1,0.999253354069792,40.0298881530762,2.00221213989424,11.5799997001886,-1.27700919440418,-0.295615790828107,25,-0.00326171693446941,-0.237355471490082,-0.0125538384216839,30.0271931,30.0281525,35118.28515625,35139.375,49.6678026260052,18.4330297185712,7.059639,0,0,0,40,4965,30.0895,35128.830078125,,,,,,,,,,,,,0,,,,1.0903405,,,,,,30.0276728,,,,
,40031735.74,30.0229969,38711.45703125,-0.233925219456236,6.53631509026109E-5,1,0.999253354069792,40.0298881530762,2.00239800525743,11.5799997001886,-1.20832516105501,-0.280074414135949,25,-0.00307527953263032,-0.224580254374788,-0.0119415389582063,30.0229969,30.0229969,38700.9921875,38721.921875,49.023740726159,18.4347573617621,7.799073,0,0,0,40,4965,30.0487,38711.45703125,,,,,,,,,,,,,0,,,,1.0903405,,,,,,30.0229969,,,,
,40031792.04,29.9954987,42650.662109375,-0.220730902902361,6.85907791124539E-5,1,0.999253354069792,40.0298881530762,2.00211843200011,11.5900002419949,-1.14235041797436,-0.26520979970251,25,-0.00293140141640303,-0.212360513246996,-0.0113674088142475,29.9954987,29.9954987,42647.27734375,42654.046875,48.5406943012744,18.4296119743627,7.799073,0,0,0,40,4965,30.05635,42650.662109375,,,,,,,,,,,,,0,,,,1.0795023,,,,,,29.9954987,,,,
,40031850.235,29.995966,46723.51171875,-0.208656210585633,6.89256226059405E-5,1,0.999253354069792,40.0298881530762,2.00226507806114,11.5900002419949,-1.08215067548518,-0.251708693766814,25,-0.00283535021613945,-0.201170108443459,-0.0108524116421967,29.995966,29.995966,46713.078125,46733.9453125,49.2003887715052,18.4285983627585,7.059639,0,0,0,40,4965,30.062,46723.51171875,,,,,,,,,,,,,0,,,,1.0688253,,,,,,29.995966,,,,
,40031908.39,29.9945526,50792.302734375,-0.197882385962718,8.01127063678785E-5,1,0.999253354069792,40.0298881530762,2.00244269695865,11.5799997001886,-1.02843721077932,-0.23946411546552,25,-0.00273512004613107,-0.191176176586866,-0.0103573460738791,29.9945526,29.9945526,50778.27734375,50806.328125,49.1261340621783,18.4372236543262,6.689921,0,0,0,40,4965,30.0655,50792.302734375,,,,,,,,,,,,,0,,,,1.0795023,,,,,,29.9945526,,,,
,40031963.125,30.1177006,54623.0078125,-0.188318977679014,7.48459589865212E-5,1,0.999253354069792,40.0298881530762,2.00224199769275,11.5799997001886,-0.98045985452926,-0.228507976691721,25,-0.00266040599321435,-0.182282253724139,-0.00991353318638315,30.1177006,30.1177006,54612.49609375,54633.51953125,49.8210018157745,18.4319898433063,7.799073,0,0,0,40,4965,30.12875,54623.0078125,,,,,,,,,,,,,0,,,,1.0688253,,,,,,30.1177006,,,,
,40032014.41,30.03530975,58212.275390625,-0.180570107010491,6.96570214464812E-5,1,0.999253354069792,40.0298881530762,2.00237636833815,11.5900002419949,-0.941716363087509,-0.219669512717515,25,-0.00261465742523722,-0.17507382326437,-0.00955530662103041,30.0351791,30.0354404,58201.72265625,58222.828125,48.8439661667359,18.4328567500644,7.799073,0,0,0,40,4965,30.08235,58212.275390625,,,,,,,,,,,,,0,,,,1.0688253,,,,,,30.03530975,,,,
,40032066.13,30.0004997,61830.087890625,-0.173290144061928,7.1987771351551E-5,1,0.999253354069792,40.0298881530762,2.0024563046189,11.5799997001886,-0.905201699839224,-0.211421643972979,25,-0.00259693577226947,-0.168287355793118,-0.00923260653076796,30.0004997,30.0004997,61826.6015625,61833.57421875,49.4974076088129,18.4336458463162,7.799073,0,0,0,40,4965,30.0352,61830.087890625,,,,,,,,,,,,,0,,,,1.05288925,,,,,,30.0004997,,,,
,40032123.865,29.99887465,65890.04296875,-0.16585773992249,7.08233716403287E-5,1,0.999253354069792,40.0298881530762,2.00241275004871,11.5799997001886,-0.86791150227036,-0.20265839029223,25,-0.00252911215603071,-0.161356413092163,-0.00884287457117283,29.9988632,29.9988861,65875.9453125,65904.140625,49.2425967115437,18.4308343259236,7.799073,0,0,0,40,4965,30.06205,65890.04296875,,,,,,,,,,,,,0,,,,1.06356625,,,,,,29.99887465,,,,
,40032182,29.9968491,69985.5546875,-0.158820515551764,7.24899108773242E-5,1,0.999253354069792,40.0298881530762,2.00239216218429,11.5799997001886,-0.832412386471038,-0.194749108869233,25,-0.00255152544220291,-0.154770167418911,-0.00854908796988809,29.9968491,29.9968491,69982.0859375,69989.0234375,49.6795270537937,18.4347088216128,6.689921,0,0,0,40,4965,30.06535,69985.5546875,,,,,,,,,,,,,0,,,,1.06356625,,,,,,29.9968491,,,,
,40032239.985,29.9967346,74070.6015625,-0.152197371844381,7.01612591451536E-5,1,0.999253354069792,40.0298881530762,2.00245576235207,11.5799997001886,-0.798951741937175,-0.1871898948611,25,-0.00255991479468372,-0.148552719972552,-0.00825324289659881,29.9967346,29.9967346,74067.09375,74074.109375,49.2934025652937,18.4309562987365,7.059639,0,0,0,40,4965,30.0659,74070.6015625,,,,,,,,,,,,,0,,,,1.0476302,,,,,,29.9967346,,,,
,40032294.875,30.058363,77937.17578125,-0.146791138102394,6.74818118475491E-5,1,0.999253354069792,40.0298881530762,2.00229675261674,11.5799997001886,-0.771638560242294,-0.181019056029882,25,-0.0025802687302164,-0.143492563688941,-0.00801251253167213,30.058363,30.058363,77926.609375,77947.7421875,50.5760549653515,18.4266244257903,7.799073,0,0,0,40,4965,30.37535,77937.17578125,,,,,,,,,,,,,0,,,,1.04242335,,,,,,30.058363,,,,
,40033217.98,30.0020542,78677.08984375,0.150267909583402,5.93471038974548E-5,1,0.999253354069792,40.0298881530762,2.00252126339343,11.5900002419949,0.790666353336823,0.18299354180723,2.5,0.00220186330600792,0.146934989092239,0.00776466779585247,30.0020542,30.0020542,78673.6484375,78680.53125,48.9674634727744,18.4302041141766,7.799073,0,0,0,40,4966,30.03845,78677.08984375,,,,,,,,,,,,,0,,,,1.0476824,,,,,,30.0020542,,,,
,40033270.865,30.0475407,74999.2421875,0.15583601088881,5.00390375795063E-5,1,0.999253354069792,40.0298881530762,2.00218420449456,11.5799997001886,0.818724466434308,0.189491978768182,2.5,0.00221676953700451,0.152174339793329,0.00804235218305113,30.0475407,30.0475407,74988.8046875,75009.6796875,49.6193416578129,18.4272102691396,6.689921,0,0,0,40,4965,30.07785,74999.2421875,,,,,,,,,,,,,0,,,,1.0581483,,,,,,30.0475407,,,,
,40033321.66,30.02971075,71470.44140625,0.161485528762697,4.56718131942098E-5,1,0.999253354069792,40.0298881530762,2.00232394898237,11.5900002419949,0.847262684383893,0.196305706298292,2.5,0.00227233594226144,0.157474526503693,0.00835936930080907,30.0296154,30.0298061,71463.5,71477.3828125,49.3606226179475,18.4345162665013,7.059639,0,0,0,40,4965,30.07905,71470.44140625,,,,,,,,,,,,,0,,,,1.0581483,,,,,,30.02971075,,,,
,40033376.215,29.9983997,67673.765625,0.16780644756284,6.12125335396805E-5,1,0.999253354069792,40.0298881530762,2.00238650790922,11.5799997001886,0.879037893022389,0.203939008228186,2.5,0.00234710499201613,0.163383919123326,0.00872103015805918,29.9983997,29.9983997,67659.9296875,67687.6015625,50.5330653967938,18.4338998254736,7.799073,0,0,0,40,4965,30.0637,67673.765625,,,,,,,,,,,,,0,,,,1.0476824,,,,,,29.9983997,,,,
,40033434.795,29.99846075,63602.5,0.175065435156003,7.09494493753513E-5,1,0.999253354069792,40.0298881530762,2.00230493069659,11.5900002419949,0.915396266932321,0.212574323297364,2.5,0.0024239710499124,0.170154794153755,0.00911783360156373,29.9983711,29.9985504,63592.12109375,63612.87890625,49.5396155488514,18.4353646635306,7.799073,0,0,0,40,4965,30.0643,63602.5,,,,,,,,,,,,,0,,,,1.0269065,,,,,,29.99846075,,,,
,40033492.805,29.9961214,59570.328125,0.182653976512896,7.50216499492404E-5,1,0.999253354069792,40.0298881530762,2.00240337737828,11.5799997001886,0.953349041048412,0.221648403461169,2.5,0.00252537945647403,0.177209211747759,0.00954194807117773,29.9960346,29.9962082,59559.8359375,59580.8203125,50.0500189719091,18.4340103960926,7.059639,0,0,0,40,4965,30.0669,59570.328125,,,,,,,,,,,,,0,,,,1.0269065,,,,,,29.9961214,,,,
,40033551.215,29.9983425,55506.53515625,0.191035191989995,7.73307059317912E-5,1,0.999253354069792,40.0298881530762,2.00238745352119,11.5799997001886,0.995220324100288,0.231266099319555,2.5,0.00258062950112186,0.18499001987763,0.0099401921323596,29.9983425,29.9983425,55499.6484375,55513.421875,49.1910092292744,18.4315537402366,7.059639,0,0,0,40,4965,30.06915,55506.53515625,,,,,,,,,,,,,0,,,,1.03726835,,,,,,29.9983425,,,,
,40033608.375,29.9996967,51533.271484375,0.200048560784153,6.98655577587441E-5,1,0.999253354069792,40.0298881530762,2.00227326500963,11.5900002419949,1.04013198194579,0.241576988689038,2.5,0.00265607264313783,0.193344924433953,0.0103669274496665,29.9996967,29.9996967,51522.8125,51543.73046875,48.4586233067551,18.4354833294854,7.799073,0,0,0,40,4965,30.06985,51533.271484375,,,,,,,,,,,,,0,,,,1.0476302,,,,,,29.9996967,,,,
,40033665.69,29.9992085,47546.181640625,0.210074880834776,6.77600679846599E-5,1,0.999253354069792,40.0298881530762,2.00239088192773,11.5799997001886,1.09018461556191,0.2529391437208,2.5,0.00273623660834,0.202629070654692,0.0108182384591512,29.9992085,29.9992085,47539.28515625,47553.078125,49.5130401791975,18.4327542926934,7.799073,0,0,0,40,4965,30.0705,47546.181640625,,,,,,,,,,,,,0,,,,1.03726835,,,,,,29.9992085,,,,
,40033723.07,29.9996147,43558.328125,0.221519699412488,6.51674945021974E-5,1,0.999253354069792,40.0298881530762,2.00243617564312,11.5900002419949,1.14726196362626,0.265909900910444,25,0.00285350062200474,0.21322669661319,0.01133592220168,29.9996147,29.9996147,43547.9296875,43568.7265625,50.1203655386399,18.4374404671407,7.059639,0,0,0,40,4961,30.07065,43558.328125,,,,,,,,,,,,,0,,,,1.03726835,,,,,,29.9996147,,,,
,40033779.165,30.0009995,39654.7109375,0.233946224166981,6.71588052369475E-5,1,0.999253354069792,40.0298881530762,2.00233575397381,11.5900002419949,1.20907878326502,0.280010104751642,25,0.00301644032122512,0.224719605199308,0.0119066741305729,30.0009995,30.0009995,39640.8125,39668.609375,49.6381007422745,18.4305887661976,7.059639,0,0,0,40,4961,30.0688,39654.7109375,,,,,,,,,,,,,0,,,,1.0269065,,,,,,30.0009995,,,,
,40033834.685,29.9999466,35796.732421875,0.247966435228761,5.99075040845509E-5,1,0.999253354069792,40.0298881530762,2.0025117616552,11.5799997001886,1.27904495336831,0.295763945050268,25,0.00319004864788543,0.237688995285483,0.0125143270865503,29.9999466,29.9999466,35789.76953125,35803.6953125,49.6381007422745,18.438934224603,7.799073,0,0,0,40,4961,30.0695,35796.732421875,,,,,,,,,,,,,0,,,,1.0476302,,,,,,29.9999466,,,,
,40033888.51,29.9997177,32056.3359375,0.263876833045608,6.18374483266022E-5,1,0.999253354069792,40.0298881530762,2.00234688977628,11.5900002419949,1.35829113934087,0.313599804145562,25,0.00341334695657127,0.252420427344062,0.0132034522991002,29.9997177,29.9997177,32042.40625,32070.265625,49.3410819049668,18.4375425136898,7.059639,0,0,0,40,4961,30.0697,32056.3359375,,,,,,,,,,,,,0,,,,1.03726835,,,,,,29.9997177,,,,
,40033943.21,29.9994602,28239.0546875,0.283124527469447,6.04273636945247E-5,1,0.999253354069792,40.0298881530762,2.00225019428215,11.5799997001886,1.45432599525926,0.335186430461465,25,0.00370797746718913,0.270261504972646,0.0140330436095223,29.9993896,29.9995308,28221.763671875,28256.345703125,49.9570051781207,18.4355200126019,7.799073,0,0,0,40,4961,30.0699,28239.0546875,,,,,,,,,,,,,0,,,,1.0476302,,,,,,29.9994602,,,,
,40033998.525,30.0012512,24381.1328125,0.306459600371478,5.5647413509125E-5,1,0.999253354069792,40.0298881530762,2.00221364968636,11.5799997001886,1.57095779331959,0.361266514176333,25,0.0040728300430994,0.291915488750549,0.0150157325344073,30.0012512,30.0012512,24377.720703125,24384.544921875,49.5912030311206,18.4317999407536,7.799073,0,0,0,40,4961,30.0703,24381.1328125,,,,,,,,,,,,,0,,,,1.0476302,,,,,,30.0012512,,,,
,40034052.85,30.0008316,20593.2900390625,0.33597194781374,5.34877956979689E-5,1,0.999253354069792,40.0298881530762,2.00233437241878,11.5799997001886,1.71895175550531,0.394382975246803,25,0.00455974408952957,0.319368067760748,0.0162655837198322,30.0008316,30.0008316,20582.984375,20603.595703125,49.463797582486,18.4357454345276,7.799073,0,0,0,40,4961,30.0688,20593.2900390625,,,,,,,,,,,,,0,,,,1.0476302,,,,,,30.0008316,,,,
,40034109.63,30.0011749,16628.158203125,0.376451593824223,5.44114870534922E-5,1,0.999253354069792,40.0298881530762,2.00228855150092,11.5900002419949,1.9221740188619,0.439810508299365,25,0.0052429540535653,0.357095424131397,0.0179750189247223,30.0011749,30.0011749,16614.28125,16642.03515625,48.7532972585052,18.4359865451992,7.059639,0,0,0,40,4961,30.0694,16628.158203125,,,,,,,,,,,,,0,,,,1.0269065,,,,,,30.0011749,,,,
,40034166.515,30.0017948,12657.5063476563,0.434482495776178,7.5200034476183E-5,1,0.999253354069792,40.0298881530762,2.00241196233681,11.5799997001886,2.21446118182507,0.504833313571216,25,0.00616541018248044,0.411312446583427,0.0203758281062857,30.0017948,30.0017948,12647.099609375,12667.9130859375,49.7623796768322,18.4404094728792,7.059639,0,0,0,40,4961,30.0683,12657.5063476563,,,,,,,,,,,,,0,,,,1.0476302,,,,,,30.0017948,,,,
,40034221.89,30.0010166,8786.72412109375,0.523513862524501,0.000115968745098224,1,0.999253354069792,40.0298881530762,2.00223588929116,11.5799997001886,2.66324394851099,0.605995645399058,25,0.00779526890965082,0.494675305319656,0.0243024363597308,30.0010166,30.0010166,8776.224609375,8797.2236328125,50.1039513397361,18.4369563613337,7.059639,0,0,0,40,4961,30.06785,8786.72412109375,,,,,,,,,,,,,0,,,,1.03726835,,,,,,30.0010166,,,,
,40034276.93,30.0010643,4942.1650390625,0.697610057254698,0.000241069949327388,1,0.999253354069792,40.0298881530762,2.0026094504418,11.5799997001886,3.54405456566727,0.803973262024198,25,0.0107170439859392,0.658081856175921,0.0318979963455991,30.0010643,30.0010643,4938.595703125,4945.734375,49.8991646676976,18.4368573003943,7.799073,0,0,0,40,4961,30.0681,4942.1650390625,,,,,,,,,,,,,0,,,,1.0476302,,,,,,30.0010643,,,,
,40034332.705,30.0017319,1034.39251708984,1.01713410983391,0.000264193048198737,1,0.999253354069792,40.0298881530762,2.00215171321779,11.5900002419949,5.15919788646414,1.16844173236558,25,0.0163364390777107,0.958144366842351,0.0461008716185883,30.0017319,30.0017319,1027.40832519531,1041.37670898438,49.6920331101014,18.4381873418313,7.799073,0,0,0,40,4961,30.0678,1034.39251708984,,,,,,,,,,,,,0,,,,1.0476302,,,,,,30.0017319,,,,
,40034387.08,30.0011883,-2760.59033203125,0.917649548869804,0.000352228071572193,1,0.999253354069792,40.0298881530762,2.00255581071629,11.5799997001886,4.65820320615198,1.05488032018937,25,0.0143182924032784,0.864928486909205,0.04159856388558,30.0011883,30.0011883,-2764.04174804687,-2757.13891601562,49.809277387986,18.4388429978221,7.799073,0,0,0,40,4961,30.0664,-2760.59033203125,,,,,,,,,,,,,0,,,,1.0425274,,,,,,30.0011883,,,,
,40034442.255,30.0028172,-6627.33569335938,0.613044797694595,0.000197918069261957,1,0.999253354069792,40.0298881530762,2.0024743719489,11.5799997001886,3.11632345899875,0.707605957211306,25,0.00924105796737324,0.578717088922211,0.0281686444682902,30.0028172,30.0028172,-6637.775390625,-6616.89599609375,49.9460623788514,18.4409124757918,7.799073,0,0,0,40,4961,30.0648,-6627.33569335938,,,,,,,,,,,,,0,,,,1.0581483,,,,,,30.0028172,,,,
,40034492.47,30.0033569,-10141.2924804688,0.490200777024106,0.000106323270743885,1,0.999253354069792,40.0298881530762,2.00232212142297,11.5799997001886,2.4954006645455,0.568124563580589,25,0.00716640757468629,0.463490439860112,0.0228270387576074,30.0033569,30.0033569,-10151.7822265625,-10130.802734375,50.4283271752169,18.4333129814984,7.059639,0,0,0,40,4961,30.0645,-10141.2924804688,,,,,,,,,,,,,0,,,,1.0425274,,,,,,30.0033569,,,,
,40034541.64,30.002203,-13583.822265625,0.419888845893753,8.32432858718063E-5,1,0.999253354069792,40.0298881530762,2.00246742747844,11.5799997001886,2.14097703957653,0.488827444002899,25,0.00599124601356819,0.397676329562414,0.0198324204173719,30.002203,30.002203,-13587.376953125,-13580.267578125,49.2676088241591,18.4379117838957,7.799073,0,0,0,40,4961,30.062,-13583.822265625,,,,,,,,,,,,,0,,,,1.04242335,,,,,,30.002203,,,,
,40034592.97,30.0019398,-17173.71875,0.3703257308485,7.41469663560132E-5,1,0.999253354069792,40.0298881530762,2.00240454760763,11.5799997001886,1.89150030235011,0.432970770815835,25,0.00514094357678401,0.351382740686504,0.0177190827059836,30.0019398,30.0019398,-17184.296875,-17163.140625,49.6029274589091,18.43743295594,7.059639,0,0,0,40,4961,30.06195,-17173.71875,,,,,,,,,,,,,0,,,,1.0425274,,,,,,30.0019398,,,,
,40034645.4,30.0026321,-20844.0380859375,0.332841244304305,7.18203234695415E-5,1,0.999253354069792,40.0298881530762,2.00247393041571,11.5900002419949,1.70321365681005,0.39105442746632,25,0.00455191802891033,0.316431440498929,0.0161659683621555,30.0026321,30.0026321,-20858.056640625,-20830.01953125,49.5153850647552,18.4319012004086,7.059639,0,0,0,40,4961,30.06,-20844.0380859375,,,,,,,,,,,,,0,,,,1.0320615,,,,,,30.0026321,,,,
,40034694.855,30.0014286,-24304.865234375,0.305535919172113,6.2774208136234E-5,1,0.999253354069792,40.0298881530762,2.00246348610373,11.5900002419949,1.56630359129606,0.360360918724983,25,0.00409623010812461,0.291020429473061,0.0149988347053319,30.0014286,30.0014286,-24308.30859375,-24301.421875,49.057350752486,18.4364303063243,7.059639,0,0,0,40,4961,30.0611,-24304.865234375,,,,,,,,,,,,,0,,,,1.0425274,,,,,,30.0014286,,,,
,40034744.93,30.0023594,-27811.0673828125,0.283395682963776,7.43362871507794E-5,1,0.999253354069792,40.0298881530762,2.00236967149592,11.5799997001886,1.45541889017107,0.335566629804172,25,0.00375539289941657,0.270452909018995,0.0140656839924504,30.0023594,30.0023594,-27821.560546875,-27800.57421875,49.4426936124668,18.4418701069723,7.799073,0,0,0,40,4961,30.05825,-27811.0673828125,,,,,,,,,,,,,0,,,,1.0476824,,,,,,30.0023594,,,,
,40034794.9,30.0024529,-31305.6943359375,0.264908834117747,7.81170351539029E-5,1,0.999253354069792,40.0298881530762,2.00257682422692,11.5799997001886,1.36312224221326,0.314978112266178,25,0.00350138302136128,0.253298148315073,0.013295871378444,30.0024529,30.0024529,-31312.7421875,-31298.646484375,50.0679964278515,18.4374435278174,7.059639,0,0,0,40,4961,30.0578,-31305.6943359375,,,,,,,,,,,,,0,,,,1.0581483,,,,,,30.0024529,,,,
,40034845.185,30.0018501,-34828.90234375,0.249165568745678,6.32959021012677E-5,1,0.999253354069792,40.0298881530762,2.00257201897163,11.5799997001886,1.2845233960173,0.297272107568417,25,0.00327402807313477,0.23870767151852,0.0126106493398256,30.0018501,30.0018501,-34839.38671875,-34818.41796875,50.1602285931207,18.4381095450317,7.059639,0,0,0,40,4961,30.0577,-34828.90234375,,,,,,,,,,,,,0,,,,1.0476824,,,,,,30.0018501,,,,
,40034897.275,30.0018082,-38467.8828125,0.234890328350889,6.32874337494772E-5,1,0.999253354069792,40.0298881530762,2.00256832462916,11.5799997001886,1.21322654448635,0.281347997185081,25,0.00311724614088008,0.225476862929495,0.0120135343010354,30.0018082,30.0018082,-38478.44140625,-38457.32421875,50.3376582669861,18.4381052366119,7.059639,0,0,0,40,4961,30.0556,-38467.8828125,,,,,,,,,,,,,0,,,,1.0476824,,,,,,30.0018082,,,,
,40034950.705,30.0019341,-42208.357421875,0.22227890810242,6.77646838347885E-5,1,0.999253354069792,40.0298881530762,2.00237317106539,11.5799997001886,1.15018518727061,0.267258302481332,25,0.00299827785814342,0.213797691874079,0.0114849444387544,30.0019341,30.0019341,-42215.2890625,-42201.42578125,50.2337016739284,18.4401755077529,7.059639,0,0,0,40,4961,30.05525,-42208.357421875,,,,,,,,,,,,,0,,,,1.0581483,,,,,,30.0019341,,,,
,40035001.125,30.0004139,-45742.359375,0.211410313373655,8.2719486837389E-5,1,0.999253354069792,40.0298881530762,2.00253356656929,11.5900002419949,1.0960324615305,0.254856990128767,25,0.00286131164927701,0.203721536993231,0.010975795994127,30.0004139,30.0004139,-45749.40234375,-45735.31640625,48.983096043159,18.4374300994391,7.059639,0,0,0,40,4961,30.05455,-45742.359375,,,,,,,,,,,,,0,,,,1.0372165,,,,,,30.0004139,,,,
,40035050.985,30.0015736,-49230.388671875,0.201876336946032,7.97903597233102E-5,1,0.999253354069792,40.0298881530762,2.0022974477414,11.5799997001886,1.04828598088408,0.244111479673602,25,0.00279223022113911,0.194880456621134,0.0105625820524607,30.0015736,30.0015736,-49240.80859375,-49219.96875,49.9390277221784,18.4351214162969,7.799073,0,0,0,40,4961,30.05405,-49230.388671875,,,,,,,,,,,,,0,,,,1.0476824,,,,,,30.0015736,,,,
,40035100.635,30.0015564,-52701.251953125,0.19303642218995,8.72288851072289E-5,1,0.999253354069792,40.0298881530762,2.0027496696171,11.5799997001886,1.00431567587896,0.233987732042071,25,0.00270075962258714,0.186668740270471,0.0101379266163668,30.0015564,30.0015564,-52718.8046875,-52683.69921875,50.2055630472361,18.4390879716728,6.689921,0,0,0,40,4961,30.0535,-52701.251953125,,,,,,,,,,,,,0,,,,1.0372165,,,,,,30.0015564,,,,
,40035150.04,30.0026493,-56158.2421875,0.185218779006353,7.89970514520008E-5,1,0.999253354069792,40.0298881530762,2.00242100660794,11.5799997001886,0.965047144039808,0.22507800179359,25,0.00265697239946372,0.179406269086647,0.00978579481245681,30.0026493,30.0026493,-56161.68359375,-56154.80078125,49.849922070986,18.443978135406,7.059639,0,0,0,40,4961,30.0534,-56158.2421875,,,,,,,,,,,,,0,,,,1.0372165,,,,,,30.0026493,,,,
,40035200.195,30.0010757,-59671.48046875,0.177729836202203,7.5770432345179E-5,1,0.999253354069792,40.0298881530762,2.00252619638338,11.5799997001886,0.927534543631144,0.216597331461035,25,0.00263107162913095,0.172432145316685,0.00945284822798364,30.0010757,30.0010757,-59688.9453125,-59654.015625,49.6115253726206,18.4371750231306,7.059639,0,0,0,40,4961,30.0521,-59671.48046875,,,,,,,,,,,,,0,,,,1.0372165,,,,,,30.0010757,,,,
,40035250.955,30.000906,-63226.310546875,0.170890057451436,7.31230643500265E-5,1,0.999253354069792,40.0298881530762,2.00260573619821,11.5799997001886,0.893308647591227,0.208536589239629,25,0.00255918136054756,0.166060839702735,0.00909148710838737,30.000906,30.000906,-63229.796875,-63222.82421875,49.5544664907168,18.4345432909297,7.059639,0,0,0,40,4961,30.0522,-63226.310546875,,,,,,,,,,,,,0,,,,1.0476824,,,,,,30.000906,,,,
,40035301.315,30.0020866,-66769.10546875,0.164431093212264,7.37835472741311E-5,1,0.999253354069792,40.0298881530762,2.00232607988226,11.5799997001886,0.860656880682647,0.201299527863957,25,0.00258069289302097,0.160024991657961,0.00882916669478987,30.0020866,30.0020866,-66786.765625,-66751.4453125,49.6044907159476,18.4368133440634,7.059639,0,0,0,40,4961,30.0503,-66769.10546875,,,,,,,,,,,,,0,,,,1.0476824,,,,,,30.0020866,,,,
,40035352.375,30.0019903,-70368.41015625,0.158208042370517,7.61025694807333E-5,1,0.999253354069792,40.0298881530762,2.00259369293342,11.5799997001886,0.829352614647732,0.194300010456228,25,0.00259587540988805,0.154194538812364,0.00856445496528882,30.0019474,30.0020332,-70378.9375,-70357.8828125,50.2626219291399,18.4368206447446,7.059639,0,0,0,40,4961,30.0497,-70368.41015625,,,,,,,,,,,,,0,,,,1.0581483,,,,,,30.0019903,,,,
,40035403.58,30.0008316,-73973.94921875,0.152380853099831,7.00951333687465E-5,1,0.999253354069792,40.0298881530762,2.0025861613683,11.5799997001886,0.799973811317526,0.187229478866257,25,0.00252505714097972,0.148727018351806,0.00822758916452197,30.0008316,30.0008316,-73984.5625,-73963.3359375,49.5786969748129,18.4403690914095,7.799073,0,0,0,40,4961,30.0501,-73973.94921875,,,,,,,,,,,,,0,,,,1.05299425,,,,,,30.0008316,,,,
,40035453.895,30.0016804,-77519.8984375,0.147075977509852,6.13783059172721E-5,1,0.999253354069792,40.0298881530762,2.00262541875589,11.5900002419949,0.773098725640542,0.181265775274887,25,0.00255657680621737,0.143738071306099,0.00800928217447274,30.0016804,30.0016804,-77526.96875,-77512.828125,50.483041171563,18.4388423232009,7.059639,0,0,0,40,4961,30.05005,-77519.8984375,,,,,,,,,,,,,0,,,,1.0372165,,,,,,30.0016804,,,,
,40035522.035,30.000473,-78988.3203125,-0.144087179210809,0.000111862582314564,1,0.999253354069792,40.0298881530762,2.00245715252836,11.570000089705,-0.758243659564826,-0.175317391577805,2.5,-0.00208588108635282,-0.140908630407318,-0.00741575462732146,30.000473,30.000473,-78998.6953125,-78977.9453125,50.8449351759669,18.435832754111,7.799073,0,0,0,40,4961,30.0493,-78988.3203125,,,,,,,,,,,,,0,,,,1.0476824,,,,,,30.000473,,,,
,40035572.06,30.0008507,-75512.47265625,-0.155418787832048,5.48988186845303E-5,1,0.999253354069792,40.0298881530762,2.00256366715845,11.5799997001886,-0.816813432739055,-0.189157747698315,2.5,-0.00223919008965131,-0.15179449700241,-0.00804139339242787,30.0008507,30.0008507,-75522.90625,-75502.0390625,49.5232013499475,18.4369182829598,7.799073,0,0,0,40,4961,30.05065,-75512.47265625,,,,,,,,,,,,,0,,,,1.06346015,,,,,,30.0008507,,,,
,40035622.43,30.0008812,-72012.046875,-0.160857760928488,5.60733383499691E-5,1,0.999253354069792,40.0298881530762,2.00236862118156,11.5799997001886,-0.844120404207118,-0.195772321159964,2.5,-0.00230754593893862,-0.156893214085324,-0.00836294414268937,30.0008812,30.0008812,-72025.9921875,-71998.1015625,49.2269641411591,18.436732943517,7.799073,0,0,0,40,4961,30.0488,-72012.046875,,,,,,,,,,,,,0,,,,1.0476824,,,,,,30.0008812,,,,
,40035673.175,30.0001678,-68484.04296875,-0.166568737697584,7.32762022444594E-5,1,0.999253354069792,40.0298881530762,2.00254260304243,11.570000089705,-0.872904904513614,-0.202536928204589,2.5,-0.00234611329433568,-0.162232325231211,-0.0086632376750483,30.0001678,30.0001678,-68494.5546875,-68473.53125,50.6745401587746,18.4406318426962,7.059639,0,0,0,40,4961,30.0496,-68484.04296875,,,,,,,,,,,,,0,,,,1.0372165,,,,,,30.0001678,,,,
,40035724.375,30.0000153,-64921.4296875,-0.172677493336572,8.14875471735835E-5,1,0.999253354069792,40.0298881530762,2.00275356027066,11.5799997001886,-0.903620545911407,-0.209833408217984,2.5,-0.00240792085569775,-0.167929027657633,-0.00899744283684061,30.0000153,30.0000153,-64935.359375,-64907.5,49.2035152855821,18.4414918575023,7.799073,0,0,0,40,4961,30.0507,-64921.4296875,,,,,,,,,,,,,0,,,,1.0581483,,,,,,30.0000153,,,,
,40035775.115,30.0003242,-61392.421875,-0.179236742600986,8.1147699767831E-5,1,0.999253354069792,40.0298881530762,2.00253776794547,11.5799997001886,-0.936408329360717,-0.217379829604481,2.5,-0.00243911651367348,-0.17403847688017,-0.00931286639445918,30.0003242,30.0003242,-61402.90625,-61381.9375,49.2824597660244,18.4348032147382,6.689921,0,0,0,40,4961,30.0493,-61392.421875,,,,,,,,,,,,,0,,,,1.0476824,,,,,,30.0003242,,,,
,40035827.74,29.9977036,-57731.611328125,-0.186444569611544,7.48998453862381E-5,1,0.999253354069792,40.0298881530762,2.00222533522248,11.5799997001886,-0.97225931335507,-0.22584397629017,2.5,-0.00252184992294293,-0.180733603420361,-0.00969617623152013,29.9977036,29.9977036,-57738.546875,-57724.67578125,50.3212440680823,18.437754645025,7.799073,0,0,0,40,4961,30.0511,-57731.611328125,,,,,,,,,,,,,0,,,,1.0372165,,,,,,29.9977036,,,,
,40035877.79,29.9981155,-54255.599609375,-0.193856803401486,7.2810346694081E-5,1,0.999253354069792,40.0298881530762,2.00247245753748,11.5799997001886,-1.00938626902084,-0.234372457609289,2.5,-0.00257586508638977,-0.187609555510534,-0.0100481461668807,29.9981155,29.9981155,-54262.51171875,-54248.6875,49.9929600900053,18.4356472256925,7.799073,0,0,0,40,4961,30.0519,-54255.599609375,,,,,,,,,,,,,0,,,,1.0476824,,,,,,29.9981155,,,,
,40035928.365,29.9993401,-50738.318359375,-0.202141797425548,7.60510692612159E-5,1,0.999253354069792,40.0298881530762,2.00240596673782,11.5799997001886,-1.05071425361436,-0.243767162195175,2.5,-0.00263242937579141,-0.195290958925535,-0.0104239378462893,29.9993401,29.9993401,-50752.27734375,-50724.359375,49.1738134018514,18.4398626136097,7.059639,0,0,0,40,4961,30.0509,-50738.318359375,,,,,,,,,,,,,0,,,,1.0476824,,,,,,29.9993401,,,,
,40035978.71,29.9995213,-47237.662109375,-0.21096735774023,6.93194918254532E-5,1,0.999253354069792,40.0298881530762,2.00230871965296,11.5799997001886,-1.09456454444865,-0.254072075080364,2.5,-0.00276975938651822,-0.203454970372239,-0.0108829788332245,29.9995213,29.9995213,-47248.06640625,-47227.2578125,50.2845075276784,18.4337590140418,7.059639,0,0,0,40,4961,30.05175,-47237.662109375,,,,,,,,,,,,,0,,,,1.0372165,,,,,,29.9995213,,,,
,40036028.42,29.9989357,-43781.28125,-0.220851118721063,6.04872624150034E-5,1,0.999253354069792,40.0298881530762,2.00258195924338,11.5799997001886,-1.1440078272202,-0.265196312499834,2.5,-0.00285080577509157,-0.212605970429395,-0.0113101113908919,29.9988976,29.9989738,-43791.74609375,-43770.81640625,49.7959897031591,18.4406986014406,7.059639,0,0,0,40,4961,30.05325,-43781.28125,,,,,,,,,,,,,0,,,,1.06346015,,,,,,29.9989357,,,,
,40036080.94,29.9990501,-40130.9453125,-0.232517665519273,6.4323259813899E-5,1,0.999253354069792,40.0298881530762,2.00260344635946,11.5900002419949,-1.2021820608227,-0.27826706569078,25,-0.00296460799108799,-0.223404065370072,-0.0118111777049128,29.9990501,29.9990501,-40141.33203125,-40120.55859375,49.7530001346014,18.4406014708084,8.168791,0,0,0,40,4961,30.0539,-40130.9453125,,,,,,,,,,,,,0,,,,1.06346015,,,,,,29.9990501,,,,
,40036132.025,30.0000153,-36574.494140625,-0.245196941823852,5.03542638148036E-5,1,0.999253354069792,40.0298881530762,2.00239733985107,11.5799997001886,-1.26523959250171,-0.292462469066889,25,-0.00311729785336062,-0.235133161580651,-0.0123604537638249,30.0000153,30.0000153,-36581.44140625,-36567.546875,50.086755512313,18.4451928074252,7.799073,0,0,0,40,4961,30.05225,-36574.494140625,,,,,,,,,,,,,0,,,,1.068772,,,,,,30.0000153,,,,
,40036182.22,29.9988251,-33085.171875,-0.259439348247323,4.58865986292273E-5,1,0.999253354069792,40.0298881530762,2.00251066654886,11.5799997001886,-1.3363060930851,-0.308520510000804,25,-0.00332340681604158,-0.248314887673764,-0.0129880961274896,29.9988251,29.9988251,-33099.09375,-33071.25,49.0448446961783,18.4380638016353,7.059639,0,0,0,40,4961,30.053,-33085.171875,,,,,,,,,,,,,0,,,,1.05299425,,,,,,29.9988251,,,,
,40036231.93,29.9981251,-29626.810546875,-0.275945656441501,5.59559874380107E-5,1,0.999253354069792,40.0298881530762,2.00245121496809,11.5799997001886,-1.41866237679327,-0.327005483454585,25,-0.00356331450481362,-0.263609448176014,-0.0136944789175636,29.9981251,29.9981251,-29637.244140625,-29616.376953125,49.3504614471975,18.4349995183327,7.799073,0,0,0,40,4961,30.0532,-29626.810546875,,,,,,,,,,,,,0,,,,1.068772,,,,,,29.9981251,,,,
,40036282.305,29.9979687,-26110.642578125,-0.29556601900233,5.04240691244884E-5,1,0.999253354069792,40.0298881530762,2.00232788057552,11.5799997001886,-1.51660866419811,-0.348907920639257,25,-0.00386051393292764,-0.281805060566565,-0.0145204107928711,29.9979687,29.9979687,-26128.05078125,-26093.234375,49.5568113762745,18.4409905779345,7.799073,0,0,0,40,4961,30.05395,-26110.642578125,,,,,,,,,,,,,0,,,,1.0372165,,,,,,29.9979687,,,,
,40036332.735,29.9989071,-22591.6328125,-0.319353409284597,4.90687447146233E-5,1,0.999253354069792,40.0298881530762,2.0023601304324,11.5799997001886,-1.63563463828588,-0.37566670055931,25,-0.00427187930960185,-0.303897156287491,-0.0155483115050207,29.9989071,29.9989071,-22605.603515625,-22577.662109375,49.2480681111783,18.4409435582713,7.799073,0,0,0,40,4961,30.0547,-22591.6328125,,,,,,,,,,,,,0,,,,1.05299425,,,,,,29.9989071,,,,
,40036382.53,29.9987068,-19118.076171875,-0.349288763436614,4.98159421172704E-5,1,0.999253354069792,40.0298881530762,2.00247958529437,11.5799997001886,-1.78586146133154,-0.409283139059867,25,-0.00477634035523564,-0.331761709089927,-0.0168169811047208,29.9987068,29.9987068,-19131.978515625,-19104.173828125,50.1711713923899,18.4381463636857,7.059639,0,0,0,40,4961,30.05605,-19118.076171875,,,,,,,,,,,,,0,,,,1.0372165,,,,,,29.9987068,,,,
,40036433.69,29.9983425,-15550.119140625,-0.389350698652215,6.46000939968103E-5,1,0.999253354069792,40.0298881530762,2.00256285832842,11.5799997001886,-1.98721552087898,-0.454424040414372,25,-0.0054826049439657,-0.369120865749455,-0.0185328197100207,29.9983425,29.9983425,-15553.5458984375,-15546.6923828125,50.0547087430245,18.4380027814932,7.799073,0,0,0,40,4961,30.0559,-15550.119140625,,,,,,,,,,,,,0,,,,1.068772,,,,,,29.9983425,,,,
,40036484.33,30.0006523,-12010.7514648438,-0.445741958788908,7.33070115565726E-5,1,0.999253354069792,40.0298881530762,2.00239700840332,11.570000089705,-2.27103146882985,-0.517971446483076,25,-0.00645310907076446,-0.421830458742918,-0.0209396624461742,30.0006523,30.0006523,-12024.72265625,-11996.7802734375,50.5604223949669,18.437594763537,8.168791,0,0,0,40,4961,30.05715,-12010.7514648438,,,,,,,,,,,,,0,,,,1.0372165,,,,,,30.0006523,,,,
,40036532.6,29.9990921,-8635.66015625,-0.527324322869307,0.000111210069274622,1,0.999253354069792,40.0298881530762,2.00241826379023,11.5900002419949,-2.68272398410691,-0.610084230687843,25,-0.00781411054329759,-0.498238476821572,-0.0244166129082155,29.9990921,29.9990921,-8642.5634765625,-8628.7568359375,49.7467471064476,18.4419853538712,7.059639,0,0,0,40,4961,30.0557,-8635.66015625,,,,,,,,,,,,,0,,,,1.068772,,,,,,29.9990921,,,,
,40036582.735,29.99906635,-5129.71997070313,-0.687137339375365,0.000201012287775593,1,0.999253354069792,40.0298881530762,2.00244481198446,11.5900002419949,-3.49080723029481,-0.791931630624499,25,-0.0105293755284443,-0.648247707196317,-0.0314279788178118,29.9990349,29.9990978,-5133.1962890625,-5126.24365234375,48.9096229623513,18.4392169587042,7.799073,0,0,0,40,4961,30.0583,-5129.71997070313,,,,,,,,,,,,,0,,,,1.0476302,,,,,,29.99906635,,,,
,40036633.105,29.9987202,-1606.59924316406,-0.971279402841487,0.00029358660468846,1,0.999253354069792,40.0298881530762,2.00241301191036,11.5799997001886,-4.92810043494706,-1.11599980155336,25,-0.0154524983075647,-0.915106222667224,-0.0440117642903084,29.9987202,29.9987202,-1613.58874511719,-1599.60974121094,50.2305751598515,18.4381594137491,7.799073,0,0,0,40,4961,30.058,-1606.59924316406,,,,,,,,,,,,,0,,,,1.068772,,,,,,29.9987202,,,,
,40036743.15,29.9995413,1519.56652832031,-1.02866565758693,0.000264345806434278,1,0.999253354069792,40.0298881530762,2.00261437181283,11.570000089705,-5.21953041243055,-1.18254555305332,25,-0.0164895905875155,-0.969144582141088,-0.0467080111181301,29.9995308,29.9995518,1502.01745605469,1537.11560058594,50.1836774486976,18.4380776613188,7.059639,0,0,0,40,4961,30.0599,1519.56652832031,,,,,,,,,,,,,0,,,,1.05299425,,,,,,29.9995413,,,,
,40036792.695,29.9984293,4985.4599609375,-0.711933749114829,0.0002687831496146,1,0.999253354069792,40.0298881530762,2.00253785137635,11.5799997001886,-3.61677410329982,-0.820292784339125,25,-0.0108981806514061,-0.671602702194351,-0.0325220357107048,29.99827,29.9985886,4978.4609375,4992.458984375,49.731114536063,18.4400839379984,7.799073,0,0,0,40,4961,30.05975,4985.4599609375,,,,,,,,,,,,,0,,,,1.068772,,,,,,29.9984293,,,,
,40036842.815,30.0014133,8495.2177734375,-0.538735187955654,0.000109227186678768,1,0.999253354069792,40.0298881530762,2.00255218873484,11.5799997001886,-2.74077267517008,-0.623337102621791,25,-0.00801429397022764,-0.508987789194744,-0.0249525769527112,30.0014133,30.0014133,8491.7509765625,8498.6845703125,50.2172874750245,18.437227304947,7.799073,0,0,0,40,4961,30.05885,8495.2177734375,,,,,,,,,,,,,0,,,,1.068772,,,,,,30.0014133,,,,
,40036892.82,30.0009289,11994.5493164062,-0.448740040901742,8.85211005339707E-5,1,0.999253354069792,40.0298881530762,2.00245722805056,11.5799997001886,-2.28639355129774,-0.521298472256315,25,-0.0064653099898922,-0.424665854084395,-0.0210491336553376,30.0009289,30.0009289,11984.119140625,12004.9794921875,49.985143804813,18.4360441640917,7.059639,0,0,0,40,4961,30.0586,11994.5493164062,,,,,,,,,,,,,0,,,,1.04242335,,,,,,30.0009289,,,,
,40036944.005,30.0016861,15574.4169921875,-0.390221511353212,6.50585341764964E-5,1,0.999253354069792,40.0298881530762,2.0021934795043,11.5799997001886,-1.99135177404795,-0.455263742184542,25,-0.00547231831513002,-0.36995235284067,-0.0185557789403594,30.0016804,30.0016918,15567.4599609375,15581.3740234375,49.2949658223321,18.4332400597838,7.059639,0,0,0,40,4961,30.058,15574.4169921875,,,,,,,,,,,,,0,,,,1.05299425,,,,,,30.0016861,,,,
,40036993.1,30.0007381,19013.6044921875,-0.350411512895913,5.44876328100635E-5,1,0.999253354069792,40.0298881530762,2.0021269243409,11.5799997001886,-1.79118842681197,-0.410534520100557,25,-0.00480591227647609,-0.332809413851522,-0.0168754958770505,30.0007381,30.0007381,19003.189453125,19024.01953125,50.0914452834284,18.4339773631007,7.059639,0,0,0,40,4961,30.05695,19013.6044921875,,,,,,,,,,,,,0,,,,1.0372165,,,,,,30.0007381,,,,
,40037043.925,30.0015774,22567.8037109375,-0.318772749647183,7.50221313356689E-5,1,0.999253354069792,40.0298881530762,2.00271421009333,11.5799997001886,-1.632840172608,-0.375430474957204,25,-0.00434070977005271,-0.303338432812315,-0.0155914834529766,30.0015774,30.0015774,22557.380859375,22578.2265625,49.6709291400822,18.4348911240219,7.059639,0,0,0,40,4961,30.05715,22567.8037109375,,,,,,,,,,,,,0,,,,1.0582011,,,,,,30.0015774,,,,
,40037095.88,30.0021648,26203.21875,-0.293410459216016,6.27133806918019E-5,1,0.999253354069792,40.0298881530762,2.00237363405233,11.5799997001886,-1.50557726129374,-0.346774896468917,25,-0.00390238265347235,-0.279761808631852,-0.0144867601825549,30.0021648,30.0021648,26196.158203125,26210.279296875,49.2293090267167,18.4343695784475,7.059639,0,0,0,40,4961,30.0556,26203.21875,,,,,,,,,,,,,0,,,,1.05299425,,,,,,30.0021648,,,,
,40037146.97,30.0007973,29783.2890625,-0.272569167240839,7.50744410910132E-5,1,0.999253354069792,40.0298881530762,2.0022398676416,11.5900002419949,-1.40118286383961,-0.323463965545464,25,-0.0036034270877979,-0.260403640260916,-0.0136142035822552,30.0007973,30.0007973,29772.740234375,29793.837890625,49.1245708051398,18.4320766786975,7.059639,0,0,0,40,4961,30.05555,29783.2890625,,,,,,,,,,,,,0,,,,1.068772,,,,,,30.0007973,,,,
,40037197.11,30.0009022,33289.29296875,-0.255682384807304,7.01414886814451E-5,1,0.999253354069792,40.0298881530762,2.00256881410095,11.5799997001886,-1.31702197491636,-0.304655353152257,25,-0.00337731838462367,-0.244743042870397,-0.0129051222698925,30.0009022,30.0009022,33278.7734375,33299.8125,50.2079079327938,18.4377805885521,7.059639,0,0,0,40,4961,30.05575,33289.29296875,,,,,,,,,,,,,0,,,,1.0582011,,,,,,30.0009022,,,,
,40037248.06,30.0018692,36854.654296875,-0.2409012639907,7.66850087339761E-5,1,0.999253354069792,40.0298881530762,2.00228608204996,11.5799997001886,-1.24305742276137,-0.288016757520644,25,-0.00318216883104787,-0.23104480319885,-0.0122661449255154,30.0018673,30.0018711,36840.6953125,36868.61328125,50.0179722026207,18.4345448442608,7.799073,0,0,0,40,4961,30.0545,36854.654296875,,,,,,,,,,,,,0,,,,1.04242335,,,,,,30.0018692,,,,
,40037298.97,30.0014038,40418.82421875,-0.228244401014468,8.01870734131512E-5,1,0.999253354069792,40.0298881530762,2.0023829085094,11.5799997001886,-1.18000927438129,-0.273786821788957,25,-0.00302595859178767,-0.219327738800146,-0.0117110103009669,30.0013943,30.0014133,40408.30078125,40429.34765625,49.1652154881398,18.4367836279271,7.059639,0,0,0,40,4961,30.054,40418.82421875,,,,,,,,,,,,,0,,,,1.0372165,,,,,,30.0014038,,,,
,40037350.775,30.0017376,44043.380859375,-0.216523759696552,8.07826436559283E-5,1,0.999253354069792,40.0298881530762,2.00254637388532,11.5900002419949,-1.12161431649612,-0.260498572472457,25,-0.00288352254383426,-0.208465515034014,-0.0111771124890785,30.0016594,30.0018158,44032.875,44053.88671875,49.6435721419091,18.4409446186028,7.059639,0,0,0,40,4961,30.05365,44043.380859375,,,,,,,,,,,,,0,,,,1.068772,,,,,,30.0017376,,,,
,40037400.84,30.0012722,47549.78125,-0.206334658051016,7.48949931634907E-5,1,0.999253354069792,40.0298881530762,2.00227191216109,11.5799997001886,-1.07058634925224,-0.248912742640511,25,-0.00278277267912201,-0.19901631372449,-0.0107174590279874,30.0012722,30.0012722,47539.13671875,47560.42578125,50.2970135839861,18.4387216543444,7.799073,0,0,0,40,4961,30.05225,47549.78125,,,,,,,,,,,,,0,,,,1.068772,,,,,,30.0012722,,,,
,40037486.665,30.00075815,48957.90234375,0.174959354534104,0.00032919950210815,1,0.999253354069792,40.0298881530762,2.00233111614008,11.5799997001886,0.908509177156185,0.211093749181323,2.5,0.00233421649752598,0.168876203061448,0.00907032403911837,30.0005722,30.0009441,48947.52734375,48968.27734375,49.5646276614668,18.4310105240677,7.799073,0,0,0,40,4961,30.05315,48957.90234375,,,,,,,,,,,,,0,,,,1.068772,,,,,,30.00075815,,,,
,40037537.025,29.9993782,45460.5390625,0.216053121483783,7.01409376548361E-5,1,0.999253354069792,40.0298881530762,2.00222866914032,11.5900002419949,1.11991358744376,0.259778983948083,2.5,0.0028098525146995,0.208169321137938,0.0111038178221243,29.9993782,29.9993782,45453.59765625,45467.48046875,49.6693658830437,18.434351737206,7.799073,0,0,0,40,4961,30.0537,45460.5390625,,,,,,,,,,,,,0,,,,1.0582011,,,,,,29.9993782,,,,
,40037589.92,30.0010605,41783.57421875,0.227151000430294,6.72001390676117E-5,1,0.999253354069792,40.0298881530762,2.00231765436196,11.5799997001886,1.17530399454665,0.272092449819327,25,0.00288457307102837,0.218441124759672,0.0115570711700223,30.0010605,30.0010605,41769.62890625,41797.51953125,49.3238860775437,18.4366510079041,7.059639,0,0,0,40,4961,30.0525,41783.57421875,,,,,,,,,,,,,0,,,,1.0372165,,,,,,30.0010605,,,,
,40037641.27,29.9992638,38210.21875,0.239104487502299,6.66369217593903E-5,1,0.999253354069792,40.0298881530762,2.00226267477191,11.5799997001886,1.23476481868072,0.285711965870306,25,0.00306185200266418,0.229494008422423,0.0121159921674345,29.9992638,29.9992638,38189.2890625,38231.1484375,50.1102043678899,18.4379719562568,7.059639,0,0,0,40,4961,30.05275,38210.21875,,,,,,,,,,,,,0,,,,1.0582011,,,,,,29.9992638,,,,
,40037692.665,29.9999084,34636.4765625,0.252639999329939,6.40823171460681E-5,1,0.999253354069792,40.0298881530762,2.00243817177428,11.5799997001886,1.30229183414262,0.300982160278486,25,0.00325079370567879,0.242012751196685,0.0127141383068693,29.9999084,29.9999084,34629.56640625,34643.38671875,49.667020997486,18.4354223427148,7.059639,0,0,0,40,4961,30.05345,34636.4765625,,,,,,,,,,,,,0,,,,1.0476302,,,,,,29.9999084,,,,
,40037742.65,29.9994087,31162.0771484375,0.268130238950531,6.07971087817749E-5,1,0.999253354069792,40.0298881530762,2.0027208931569,11.5900002419949,1.37975595041707,0.3184592765655,25,0.00348240144994816,0.256359660209588,0.0133924722338072,29.9994087,29.9994087,31151.53125,31172.623046875,48.5907185265051,18.4408561999601,7.799073,0,0,0,40,4961,30.0533,31162.0771484375,,,,,,,,,,,,,0,,,,1.068772,,,,,,29.9994087,,,,
,40037793.305,29.9994926,27626.091796875,0.286607946362862,6.04002236727409E-5,1,0.999253354069792,40.0298881530762,2.00216208028821,11.5799997001886,1.4716927492009,0.338923749147833,25,0.00373381399274996,0.273492193935877,0.014153852271815,29.9994926,29.9994926,27608.634765625,27643.548828125,49.6083988585437,18.4383437483839,8.168791,0,0,0,40,4961,30.0538,27626.091796875,,,,,,,,,,,,,0,,,,1.0582011,,,,,,29.9994926,,,,
,40037843.965,29.9997139,24092.7470703125,0.30887128652338,6.27102420438522E-5,1,0.999253354069792,40.0298881530762,2.00234598448467,11.5799997001886,1.58322495030665,0.363734358174664,25,0.00405787009851887,0.294164888653337,0.0150689457256763,29.9997139,29.9997139,24085.72265625,24099.771484375,50.1750795349861,18.4371628186414,7.799073,0,0,0,40,4961,30.05395,24092.7470703125,,,,,,,,,,,,,0,,,,1.0582011,,,,,,29.9997139,,,,
,40037894.04,29.9993687,20601.0478515625,0.335965338646699,5.6843936989687E-5,1,0.999253354069792,40.0298881530762,2.00235831614481,11.5799997001886,1.71897497505853,0.394161157760024,25,0.00451824310909376,0.319361502063912,0.0162250544131963,29.9993687,29.9993687,20590.685546875,20611.41015625,49.5169483217937,18.4440010702907,7.059639,0,0,0,40,4961,30.0549,20601.0478515625,,,,,,,,,,,,,0,,,,1.0372165,,,,,,29.9993687,,,,
,40037944.61,29.9986801,17072.2080078125,0.371464609869366,6.31896009899346E-5,1,0.999253354069792,40.0298881530762,2.00222610586795,11.5900002419949,1.89714609457673,0.433752408061568,25,0.00507196937793167,0.352446088062751,0.0176823172323256,29.9986801,29.9986801,17061.84765625,17082.568359375,50.1000431971399,18.4358576672938,7.059639,0,0,0,40,4961,30.05555,17072.2080078125,,,,,,,,,,,,,0,,,,1.068772,,,,,,29.9986801,,,,
,40037993.905,29.99822715,13629.8681640625,0.417777115675526,8.43409731453739E-5,1,0.999253354069792,40.0298881530762,2.00251618983579,11.5799997001886,2.13034397980886,0.486188869818045,25,0.00591748730328378,0.395685252829944,0.0196958107625633,29.9981461,29.9983082,13619.2783203125,13640.4580078125,50.0820657411976,18.4315162078205,7.059639,0,0,0,40,4961,30.05635,13629.8681640625,,,,,,,,,,,,,0,,,,1.0476302,,,,,,29.99822715,,,,
,40038044.265,29.9979897,10112.6186523438,0.486972075029117,0.000104303617065533,1,0.999253354069792,40.0298881530762,2.00223804582903,11.5799997001886,2.47884359481449,0.564207902641079,25,0.00709759986217311,0.460429378414792,0.0226502347121383,29.9979897,29.9979897,10098.626953125,10126.6103515625,49.6091804870629,18.4403878330147,8.168791,0,0,0,40,4961,30.05615,10112.6186523438,,,,,,,,,,,,,0,,,,1.04242335,,,,,,29.9979897,,,,
,40038093.055,29.9988689,6701.935546875,0.600339665155617,0.000150310922539122,1,0.999253354069792,40.0298881530762,2.0021112612778,11.5799997001886,3.0513548588332,0.692481180868271,25,0.00896916072368294,0.566740544367337,0.0275197041062424,29.9988689,29.9988689,6688.009765625,6715.861328125,49.7537817631206,18.4361603253254,7.059639,0,0,0,40,4961,30.0564,6701.935546875,,,,,,,,,,,,,0,,,,1.068772,,,,,,29.9988689,,,,
,40038142.08,29.9994583,3270.81652832031,0.82451460923296,0.000299356590311657,1,0.999253354069792,40.0298881530762,2.00243023670327,11.5799997001886,4.18584457022653,0.948356364798076,25,0.0128373184492822,0.777283143901012,0.0374620119932059,29.9994583,29.9994583,3260.33618164063,3281.296875,49.2254008841206,18.4339969257168,7.799073,0,0,0,40,4961,30.057,3270.81652832031,,,,,,,,,,,,,0,,,,1.068772,,,,,,29.9994583,,,,
,40038190.525,29.9994469,-0.343940854072571,1.04880894608714,0.000395794714452197,1,0.999253354069792,40.0298881530762,2.00254506236519,11.5799997001886,5.31967295422206,1.20382594750681,25,0.0168808414743338,0.987727679893059,0.0473543587997174,29.9994469,29.9994469,-0.343940854072571,-0.343940854072571,49.4591078113706,18.4350086838462,7.799073,0,0,0,40,4929,30.0582,-0.343940854072571,,,,,,,,,,,,,0,,,,1.05299425,,,,,,29.9994469,,,,