File: Модуль 4/5 OUT-OF-PLANE 5K 8T.DAT
[Header]
; VSM Data File (default extension .dat)
; Copyright (c) 2003-2013, Quantum Design, Inc. All rights reserved.
TITLE,NI5E11 OUT-OF-PLANE 5K 8T.DAT
FILEOPENTIME,40189118.86,04/10/2024,2:41 pm
BYAPP,VSM,2.0,2.0
INFO,PPMS VSM Option Release 1.4.10 Build 1,APPNAME
INFO,Quantum Design Linear Motor Servo Controller,MOTOR_MODULE_NAME
INFO,3101-100 E4,MOTOR_HW_VERSION
INFO,MMC433,MOTOR_SERIAL_NUMBER
INFO,SRV No X-over 01.01.11,MOTOR_SOFTWARE_VERSION
INFO,Quantum Design VSM Detection Module,VSM_MODULE_NAME
INFO,3101-150 E1,VSM_HW_VERSION
INFO,354,VSM_SERIAL_NUMBER
INFO,VSM No X-over 01.02.05 May 20 2008 13:51:47,VSM_SOFTWARE_VERSION
INFO,339,PREAMP_SERIAL_NUMBER
INFO,Quantum Design VSM Oven,OVEN_MODULE_NAME
INFO,3101-200 D0,OVEN_HW_VERSION
INFO,OVN180,OVEN_SERIAL_NUMBER
INFO,01.01.00,OVEN_SOFTWARE_VERSION
INFO,LB602,COIL_SERIAL_NUMBER
INFO,0,MOMENT_UNITS
INFO,Ni5e11 out-of-plane,SAMPLE_MATERIAL
INFO,,SAMPLE_COMMENT
INFO,,SAMPLE_MASS
INFO,,SAMPLE_VOLUME
INFO,,SAMPLE_MOLECULAR_WEIGHT
INFO,,SAMPLE_SIZE
INFO,,SAMPLE_SHAPE
DATATYPE,COMMENT,1
DATATYPE,TIME,2
STARTUPAXIS,X,2
STARTUPAXIS,Y1,5
[Data]
Comment,Time Stamp (sec),Temperature (K),Magnetic Field (Oe),Moment (emu),M. Std. Err. (emu),Transport Action,Averaging Time (sec),Frequency (Hz),Peak Amplitude (mm),Center Position (mm),Coil Signal' (mV),Coil Signal" (mV),Range (mV),M. Quad. Signal (emu),M. Raw' (emu),M. Raw" (emu),Min. Temperature (K),Max. Temperature (K),Min. Field (Oe),Max. Field (Oe),Mass (grams),Motor Lag (deg),Pressure (Torr),VSM Status (code),Motor Status (code),Measure Status (code),Measure Count,PPMS Status (code),System Temp. (K),System Field (Oe),Sample Position (deg),Bridge 1 Resistance (ohms),Bridge 1 Excitation (에),Bridge 2 Resistance (ohms),Bridge 2 Excitation (에),Bridge 3 Resistance (ohms),Bridge 3 Excitation (에),Bridge 4 Resistance (ohms),Bridge 4 Excitation (에),Signal 1 Vin (V),Signal 2 Vin (V),Digital Inputs (code),Drive 1 Iout (mA),Drive 1 Ipower (W),Drive 2 Iout (mA),Drive 2 Ipower (W),Pressure (),Map 20 (),Map 21 (),Map 22 (),Map 23 (),Map 24 (),Map 25 (),Map 26 (),Map 27 (),Map 28 (),Map 29 ()
sample offset = 35 mm touchdown = 5.59000018984079 mm,40189138.22,5.0081258,0.0156336762011051,-0.000100118486551448,1.05994971641322E-6,1,0.999253354069792,40.0298881530762,1.98864420142742,11.6200000047684,-0.000501234575244672,-0.000119013111609364,0.25,-3.06946361112016E-6,-9.38593728595174E-5,-5.49520076040468E-6,5.0081258,5.0081258,0.0156336762011051,0.0156336762011051,49.3887612446398,18.3871396827099,8.168791,0,0,0,40,4881,5.005,0.0156336762011051,,,,,,,,,,,,,0,,,,0.6550834,,,,,,5.0081258,,,,
,40189220.855,5.0057387,3891.65209960937,-1.38420100149464,0.000387637390180296,1,0.999253354069792,40.0298881530762,1.98897661701496,11.6100003942847,-6.9549645505197,-1.56544606171433,25,-0.0244551334723037,-1.29968358505709,-0.0608060000428673,5.0057387,5.0057387,3884.62524414063,3898.67895507812,49.7201717367937,18.3989930340002,8.168791,0,0,0,40,4961,5.0045,3891.65209960937,,,,,,,,,,,,,0,,,,0.6485717,,,,,,5.0057387,,,,
,40189271.555,5.0020771,7434.90454101562,-1.33218338382033,0.000241204884846676,1,0.999253354069792,40.0298881530762,1.98928121983715,11.6200000047684,-6.70308773784394,-1.51602327864877,25,-0.0230808916682953,-1.25265840408521,-0.0599016821793768,5.0020771,5.0020771,7421,7448.80908203125,48.759550286659,18.3985968058368,7.429356,0,0,0,40,4961,5.0036,7434.90454101562,,,,,,,,,,,,,0,,,,0.65511605,,,,,,5.0020771,,,,
,40189323.745,4.99902035,11088.4716796875,-1.1142147020574,0.000228311611109359,1,0.999253354069792,40.0298881530762,1.98923185102762,11.6100003942847,-5.61479839746466,-1.27546598309081,25,-0.0187571874148584,-1.04948357126661,-0.051180049466261,4.9984074,4.9996333,11074.4326171875,11102.5107421875,47.9724503677935,18.3971067372445,7.059639,0,0,0,40,4961,4.9973,11088.4716796875,,,,,,,,,,,,,0,,,,0.6616604,,,,,,4.99902035,,,,
,40189374.87,5.00046185,14667.8173828125,-0.967680200045724,0.000151733689377323,1,0.999253354069792,40.0298881530762,1.98897776587691,11.6200000047684,-4.88375979425111,-1.11439487913204,25,-0.0159160789106639,-0.91311444642687,-0.0454193878223835,5.000227,5.0006967,14657.322265625,14678.3125,49.1230075481014,18.3981786052806,8.168791,0,0,0,40,4961,5.00095,14667.8173828125,,,,,,,,,,,,,0,,,,0.65189265,,,,,,5.00046185,,,,
,40189427.555,5.00142645,18355.3193359375,-0.861023138250132,0.00015476584757502,1,0.999253354069792,40.0298881530762,1.98913765741576,11.6200000047684,-4.35383217302119,-0.997240993074913,25,-0.0137425512616838,-0.814089713327893,-0.0411648442726251,5.0013933,5.0014596,18344.853515625,18365.78515625,48.7040546617936,18.4037448895247,8.168791,0,0,0,40,4961,5.0021,18355.3193359375,,,,,,,,,,,,,0,,,,0.6421249,,,,,,5.00142645,,,,
,40189478.115,4.99970725,21891.998046875,-0.784066085593402,0.00011808380092076,1,0.999253354069792,40.0298881530762,1.98894145382806,11.6100003942847,-3.97152166504482,-0.913652737869058,25,-0.0123627090169269,-0.742802083788532,-0.0382690470986843,4.9996324,4.9997821,21885.017578125,21898.978515625,49.8553934706207,18.4041723914757,7.429356,0,0,0,40,4961,5.0016,21891.998046875,,,,,,,,,,,,,0,,,,0.64860415,,,,,,4.99970725,,,,
,40189528.995,4.99889995,25450.306640625,-0.724332619298968,9.89803773081018E-5,1,0.999253354069792,40.0298881530762,1.9891149804034,11.6100003942847,-3.67619590064046,-0.849428961660806,25,-0.0113712471427378,-0.687625996875821,-0.0360881975146788,4.998837,4.9989629,25446.787109375,25453.826171875,49.7631613053514,18.405925478916,8.168791,0,0,0,40,4961,5.0025,25450.306640625,,,,,,,,,,,,,0,,,,0.6389335,,,,,,4.99889995,,,,
,40189580.715,4.9977221,29072.3984375,-0.673664310747072,0.000118258721874065,1,0.999253354069792,40.0298881530762,1.98903956402737,11.6200000047684,-3.4258181448263,-0.794112498297295,25,-0.0104354918763695,-0.640897412930257,-0.0340873977553943,4.9977221,4.9977221,29065.435546875,29079.361328125,49.6193416578129,18.4083367026982,8.168791,0,0,0,40,4961,5.00325,29072.3984375,,,,,,,,,,,,,0,,,,0.6421569,,,,,,4.9977221,,,,
,40189634.215,4.9961858,32816.318359375,-0.629987984042704,0.000108949144568497,1,0.999253354069792,40.0298881530762,1.98931459185751,11.6200000047684,-3.21080975043796,-0.747112818211355,25,-0.00978732053188343,-0.600682944195746,-0.032454037701924,4.9956298,4.9967418,32802.37890625,32830.2578125,49.3270125916206,18.4078914248115,8.168791,0,0,0,40,4961,5.00195,32816.318359375,,,,,,,,,,,,,0,,,,0.6421569,,,,,,4.9961858,,,,
,40189686.985,4.9984002,36510.994140625,-0.594314069718282,9.40876646723688E-5,1,0.999253354069792,40.0298881530762,1.98903471290243,11.6200000047684,-3.03498734653054,-0.707900412587216,25,-0.00916977368021424,-0.567921671204758,-0.0309864645878317,4.9984002,4.9984002,36504.0234375,36517.96484375,49.2042969141014,18.4087758849322,7.429356,0,0,0,40,4961,5.008,36510.994140625,,,,,,,,,,,,,0,,,,0.6294227,,,,,,4.9984002,,,,
,40189742.995,4.9987226,40428.52734375,-0.560949696495876,6.09545392184316E-5,1,0.999253354069792,40.0298881530762,1.98895549865237,11.6200000047684,-2.87067511523248,-0.672173218257968,25,-0.0088434473882233,-0.537278029659039,-0.0297769818265078,4.9987226,4.9987226,40421.4921875,40435.5625,48.7361014310821,18.4061169928515,7.059639,0,0,0,40,4961,5.01045,40428.52734375,,,,,,,,,,,,,0,,,,0.6421249,,,,,,4.9987226,,,,
,40189798.38,4.9971404,44304.98828125,-0.532782053493328,8.24944836129299E-5,1,0.999253354069792,40.0298881530762,1.98907499386636,11.6100003942847,-2.73258731821335,-0.64138591557142,25,-0.00848861094246748,-0.5114524492551,-0.0286208476861418,4.9971404,4.9971404,44290.95703125,44319.01953125,49.7045391664091,18.4053461216876,8.168791,0,0,0,40,4961,5.0087,44304.98828125,,,,,,,,,,,,,0,,,,0.6231661,,,,,,4.9971404,,,,
,40189853.815,4.9955392,48181.705078125,-0.508231446902577,7.46991501361884E-5,1,0.999253354069792,40.0298881530762,1.98888396922626,11.6200000047684,-2.61187189417469,-0.614795817835156,25,-0.00830126811345416,-0.488959524955194,-0.027672504824132,4.9955392,4.9955392,48174.73046875,48188.6796875,49.2011704000244,18.4071465545312,8.168791,0,0,0,40,4961,5.01255,48181.705078125,,,,,,,,,,,,,0,,,,0.6357421,,,,,,4.9955392,,,,
,40189909.105,4.9960337,52055.033203125,-0.485983596799219,6.39906745889909E-5,1,0.999253354069792,40.0298881530762,1.98894478097627,11.6100003942847,-2.50275472842022,-0.59034467389544,25,-0.00811334828889213,-0.468557213799127,-0.0267373183703145,4.9960337,4.9960337,52044.45703125,52065.609375,48.5813389842744,18.4079189724592,7.429356,0,0,0,40,4961,5.01555,52055.033203125,,,,,,,,,,,,,0,,,,0.62635695,,,,,,4.9960337,,,,
,40189965.335,4.9954367,55987.427734375,-0.465990131706197,7.56244225349068E-5,1,0.999253354069792,40.0298881530762,1.98915658478851,11.6100003942847,-2.40486637437625,-0.568510264686305,25,-0.00801405194364429,-0.450223916869783,-0.0259144913339009,4.9954367,4.9954367,55976.796875,55998.05859375,49.8217834442937,18.4066992004378,7.429356,0,0,0,40,4961,5.01775,55987.427734375,,,,,,,,,,,,,0,,,,0.6169718,,,,,,4.9954367,,,,
,40190020.9,4.9943454,59874.70703125,-0.448000424961542,5.29997385913842E-5,1,0.999253354069792,40.0298881530762,1.98920110555929,11.6100003942847,-2.31659392797288,-0.548311832549099,25,-0.00787710532610511,-0.433709853407551,-0.0250829938874,4.9943385,4.9943523,59867.7421875,59881.671875,49.4372222128321,18.4102042864887,7.429356,0,0,0,40,4961,5.02135,59874.70703125,,,,,,,,,,,,,0,,,,0.6139054,,,,,,4.9943454,,,,
,40190077.065,4.99430705,63811.341796875,-0.431682511276016,4.43040791227635E-5,1,0.999253354069792,40.0298881530762,1.98912602402863,11.6100003942847,-2.23639741220379,-0.529785507578436,25,-0.00776164738549936,-0.418725418651919,-0.0242973806154961,4.9939499,4.9946642,63804.43359375,63818.25,49.5153850647552,18.4039450466587,8.168791,0,0,0,40,4961,5.0243,63811.341796875,,,,,,,,,,,,,0,,,,0.6294227,,,,,,4.99430705,,,,
,40190133.375,4.9939594,67780.40625,-0.416675412067947,4.89065283442494E-5,1,0.999253354069792,40.0298881530762,1.98917203627752,11.6200000047684,-2.16267351296405,-0.512710684497001,25,-0.00768263621642906,-0.404925158325415,-0.0235659302816943,4.9939594,4.9939594,67769.84375,67790.96875,49.4254977850437,18.4092760861502,7.429356,0,0,0,40,4961,5.02835,67780.40625,,,,,,,,,,,,,0,,,,0.610839,,,,,,4.9939594,,,,
,40190190.72,4.9936543,71819.83203125,-0.40232577156822,4.01619225035485E-5,1,0.999253354069792,40.0298881530762,1.98886062571265,11.6100003942847,-2.09149328859509,-0.49668612819519,25,-0.00771944488746968,-0.391684623599014,-0.0229466258441175,4.9936543,4.9936543,71805.7265625,71833.9375,48.3843685974282,18.4088452697549,8.168791,0,0,0,40,4961,5.03115,71819.83203125,,,,,,,,,,,,,0,,,,0.6169718,,,,,,4.9936543,,,,
,40190245.72,4.9932485,75689.66015625,-0.389847601991418,4.26309950878767E-5,1,0.999253354069792,40.0298881530762,1.98925283516305,11.6200000047684,-2.03035772235275,-0.482192967882018,25,-0.00764300019836783,-0.380163104658569,-0.0222761373632935,4.9932485,4.9932485,75679.0625,75700.2578125,49.0862710076975,18.4061674481397,8.168791,0,0,0,40,4961,5.0348,75689.66015625,,,,,,,,,,,,,0,,,,0.6169718,,,,,,4.9932485,,,,
,40190302.28,4.9926972,79676.6875,-0.378055099832512,3.46402335155197E-5,1,0.999253354069792,40.0298881530762,1.98947788444476,11.6200000047684,-1.97227194501568,-0.468691030369017,25,-0.00764177480063975,-0.36925568252096,-0.0216890986634802,4.9926972,4.9926972,79666.046875,79687.328125,49.1972622574283,18.4086384080942,7.429356,0,0,0,40,4961,5.0393,79676.6875,,,,,,,,,,,,,0,,,,0.5987558,,,,,,4.9926972,,,,
,40190437.405,4.9976687,76228.9609375,0.396220383081982,6.97803418168835E-5,1,0.999253354069792,40.0298881530762,1.98931029237602,11.6200000047684,2.06473328032985,0.48712208593891,25,0.0072039006694875,0.386486105363797,0.0220713467901942,4.9976687,4.9976687,76218.546875,76239.375,49.0862710076975,18.4091937246889,7.429356,0,0,0,40,4961,5.04225,76228.9609375,,,,,,,,,,,,,0,,,,0.59878565,,,,,,4.9976687,,,,
,40190493.915,5.0028567,72300.88671875,0.412248471684151,6.62632052651638E-5,1,0.999253354069792,40.0298881530762,1.98940625950907,11.6100003942847,2.14476578003229,0.506114937824576,25,0.00734277645255218,0.401451579289787,0.0229457699489575,5.0028567,5.0028567,72290.5,72311.2734375,50.0164089455822,18.4154312199697,7.429356,0,0,0,40,4961,5.0429,72300.88671875,,,,,,,,,,,,,0,,,,0.60182155,,,,,,5.0028567,,,,
,40190546,5.0077701,68675.26953125,0.424535186026938,6.60968225913236E-5,1,0.999253354069792,40.0298881530762,1.98890214150638,11.6200000047684,2.20454181395163,0.520408378908669,25,0.00745284807341414,0.412748303271455,0.0236248511003503,5.0077701,5.0077701,68668.3046875,68682.234375,48.7665849433321,18.4163846447944,7.429356,0,0,0,40,4961,5.0441,68675.26953125,,,,,,,,,,,,,0,,,,0.6169718,,,,,,5.0077701,,,,
,40190602.875,5.00694395,64722.623046875,0.439429762351665,7.01878599081631E-5,1,0.999253354069792,40.0298881530762,1.98912546692932,11.6100003942847,2.27796464640332,0.537545266382854,25,0.00754550997737488,0.426442071514004,0.024373882647802,5.0049381,5.0089498,64712.17578125,64733.0703125,49.2965290793706,18.4101387373631,7.429356,0,0,0,40,4961,5.0463,64722.623046875,,,,,,,,,,,,,0,,,,0.6108695,,,,,,5.00694395,,,,
,40190653.625,4.7103679,61193.630859375,0.458016114323948,0.000103897960271788,1,0.999253354069792,40.0298881530762,1.98890199443849,11.6100003942847,2.37004689817018,0.558853362572113,25,0.00769378155138662,0.443715443204359,0.025286237749955,4.673264,4.7474718,61151.97265625,61235.2890625,49.0940872928898,18.4160566793157,7.059639,0,0,0,40,4966,4.74415,61193.630859375,,,,,,,,,,,,,0,,,,0.5898578,,,,,,4.7103679,,,,
,40190705.235,5.0250835,57602.115234375,0.469457696603795,5.7646521041202E-5,1,0.999253354069792,40.0298881530762,1.9888551477226,11.6100003942847,2.42480674729312,0.571520711455,25,0.00777741236578613,0.453970138476381,0.0258270437604653,5.0250835,5.0250835,57591.66796875,57612.5625,50.2297935313322,18.4167539889585,8.168791,0,0,0,40,4965,5.0242,57602.115234375,,,,,,,,,,,,,0,,,,0.5987558,,,,,,5.0250835,,,,
,40190757.275,5.0069251,53987.15625,0.487403652734753,7.92056519105958E-5,1,0.999253354069792,40.0298881530762,1.98928512865591,11.5999998524785,2.51341884442953,0.591443948767767,25,0.00787212530960371,0.470430256427829,0.0265922702962664,5.0069251,5.0069251,53976.73828125,53997.57421875,49.0362467824667,18.4221786019371,7.429356,0,0,0,40,4965,5.01865,53987.15625,,,,,,,,,,,,,0,,,,0.61396665,,,,,,5.0069251,,,,
,40190802.065,5.0114717,50873.095703125,0.503545150905961,8.11371943278695E-5,1,0.999253354069792,40.0298881530762,1.98897901711464,11.6100003942847,2.59186307711615,0.609851084813504,25,0.00813803354586519,0.485183667659259,0.0274170038818633,5.0114717,5.0114717,50862.703125,50883.48828125,49.5185115788322,18.4171113077254,7.429356,0,0,0,40,4965,5.02035,50873.095703125,,,,,,,,,,,,,0,,,,0.6078638,,,,,,5.0114717,,,,
,40190852.15,5.0043101,47389.916015625,0.524449096943301,7.52014996717668E-5,1,0.999253354069792,40.0298881530762,1.98915609092597,11.6200000047684,2.69461363956954,0.633071423095557,25,0.00836395506269122,0.504343915967911,0.0283295700359155,5.0043101,5.0043101,47386.36328125,47393.46875,48.8775761930629,18.417984278305,8.168791,0,0,0,40,4965,5.02155,47389.916015625,,,,,,,,,,,,,0,,,,0.6047672,,,,,,5.0043101,,,,
,40190903.575,5.0020294,43812.044921875,0.54767790654517,8.55755064988372E-5,1,0.999253354069792,40.0298881530762,1.98924383677257,11.6100003942847,2.80865553915508,0.658069881864004,25,0.00853093636890279,0.525609319940771,0.029204778912259,5.0020294,5.0020294,43798.1953125,43825.89453125,48.5422575583128,18.4193466037967,8.168791,0,0,0,40,4961,5.01935,43812.044921875,,,,,,,,,,,,,0,,,,0.610839,,,,,,5.0020294,,,,
,40190960.11,5.0008135,39884.3203125,0.577298793464152,0.000102628144535958,1,0.999253354069792,40.0298881530762,1.98897295913976,11.6100003942847,2.95354764535779,0.690922544666606,25,0.00901629520672575,0.552763004274111,0.0305185414153433,5.0008135,5.0008135,39877.41015625,39891.23046875,49.7334594216207,18.4197500756934,7.429356,0,0,0,40,4961,5.0145,39884.3203125,,,,,,,,,,,,,0,,,,0.6169718,,,,,,5.0008135,,,,
,40191011.835,5.0028415,36287.234375,0.607770619350032,8.58821030186284E-5,1,0.999253354069792,40.0298881530762,1.9889571399326,11.6100003942847,3.10305506424309,0.724333426425391,25,0.00950178479464784,0.580698579288253,0.0317826386230376,5.0028415,5.0028415,36283.796875,36290.671875,49.3786000738898,18.414935966188,8.168791,0,0,0,40,4961,5.0141,36287.234375,,,,,,,,,,,,,0,,,,0.6047672,,,,,,5.0028415,,,,
,40191063.765,5.00312685,32675.2861328125,0.643702772877391,8.76164625651218E-5,1,0.999253354069792,40.0298881530762,1.9888900538206,11.6100003942847,3.27960364234284,0.763811483006284,25,0.0101466291376304,0.613702715182738,0.0332805369335927,5.0031266,5.0031271,32668.279296875,32682.29296875,49.6177784007745,18.4231534475624,8.168791,0,0,0,40,4961,5.01355,32675.2861328125,,,,,,,,,,,,,0,,,,0.6169718,,,,,,5.00312685,,,,
,40191115.02,5.0035915,29104.1083984375,0.686362960115048,0.000110038842857228,1,0.999253354069792,40.0298881530762,1.98901977071604,11.6200000047684,3.4900952895763,0.81063269900056,25,0.0109296530510061,0.652980025844092,0.0350185739641344,5.0035915,5.0035915,29100.6875,29107.529296875,49.3238860775437,18.4260802000083,7.429356,0,0,0,40,4961,5.0122,29104.1083984375,,,,,,,,,,,,,0,,,,0.6047672,,,,,,5.0035915,,,,
,40191166.57,5.0031238,25507.57421875,0.736601282710579,0.000114169184543164,1,0.999253354069792,40.0298881530762,1.989045714314,11.6100003942847,3.73801611845319,0.865899637284959,25,0.0119614992794493,0.699282450357352,0.0370892679732259,5.0031238,5.0031238,25493.54296875,25521.60546875,49.768632704986,18.4220326407479,7.429356,0,0,0,40,4961,5.01025,25507.57421875,,,,,,,,,,,,,0,,,,0.6108695,,,,,,5.0031238,,,,
,40191217.115,5.0023065,21981.419921875,0.798544775509338,0.00015843324140452,1,0.999253354069792,40.0298881530762,1.98899928146541,11.6200000047684,4.04447736226987,0.933914585378317,25,0.0132213972593364,0.756535986150353,0.0395960950025899,5.0023065,5.0023065,21970.927734375,21991.912109375,49.1136280058706,18.4207878740817,7.059639,0,0,0,40,4961,5.00785,21981.419921875,,,,,,,,,,,,,0,,,,0.6169718,,,,,,5.0023065,,,,
,40191269.125,5.0017133,18355.203125,0.879549275897128,0.000127223926023396,1,0.999253354069792,40.0298881530762,1.98919884746756,11.6100003942847,4.44650547234382,1.02409235634401,25,0.0150954057408999,0.831571378498598,0.0430506197849242,5.0017133,5.0017133,18351.78515625,18358.62109375,49.3770368168514,18.4236813544186,7.429356,0,0,0,40,4961,5.00805,18355.203125,,,,,,,,,,,,,0,,,,0.6078638,,,,,,5.0017133,,,,
,40191321.15,5.0019221,14723.1030273438,0.988349699612334,0.000156776210704723,1,0.999253354069792,40.0298881530762,1.98886826252311,11.6200000047684,4.98671509295645,1.14404785677132,25,0.0173964308939181,0.932609408419849,0.0474866337409486,5.0019221,5.0019221,14716.0615234375,14730.14453125,49.0510977243321,18.423474772029,7.429356,0,0,0,40,4961,5.00785,14723.1030273438,,,,,,,,,,,,,0,,,,0.6169718,,,,,,5.0019221,,,,
,40191372.635,5.0012665,11125.1254882813,1.14379537761394,0.000256663756443504,1,0.999253354069792,40.0298881530762,1.9889492978736,11.6100003942847,5.76094343952067,1.31978914507575,25,0.0213389916704487,1.0773021551655,0.0545189669623344,5.0012665,5.0012665,11118.1435546875,11132.107421875,49.6732740256399,18.4300685727158,7.429356,0,0,0,40,4961,5.0082,11125.1254882813,,,,,,,,,,,,,0,,,,0.5987558,,,,,,5.0012665,,,,
,40191423.795,5.0006108,7546.9990234375,1.38815191007399,0.000336404722390435,1,0.999253354069792,40.0298881530762,1.98879165642856,11.6200000047684,6.98081250585511,1.59173748239536,25,0.0264296951081198,1.30528152457912,0.0647176257121156,5.0006108,5.0006108,7540.05322265625,7553.94482421875,48.9158759905052,18.4242497583892,8.168791,0,0,0,40,4961,5.00775,7546.9990234375,,,,,,,,,,,,,0,,,,0.5987558,,,,,,5.0006108,,,,
,40191474.2,5.0010448,4022.4970703125,1.68666605826023,0.000343355246802092,1,0.999253354069792,40.0298881530762,1.98897262377849,11.6100003942847,8.47141914888956,1.92552210429049,25,0.0332682076548502,1.58366312312123,0.0774337947070587,5.0010448,5.0010448,4008.54418945313,4036.44995117188,49.7186084797553,18.4273814831831,8.168791,0,0,0,40,4961,5.00725,4022.4970703125,,,,,,,,,,,,,0,,,,0.6047974,,,,,,5.0010448,,,,
,40191525.975,5.0010958,401.706130981445,1.90352313255442,0.000253772740533149,1,0.999253354069792,40.0298881530762,1.98885517066362,11.6100003942847,9.54923375084697,2.16739575179751,25,0.0392762552349176,1.78515607248495,0.0867317551464739,5.0010958,5.0010958,398.208251953125,405.204010009766,49.138640118486,18.425167769547,8.168791,0,0,0,40,4961,5.0065,401.706130981445,,,,,,,,,,,,,0,,,,0.60182155,,,,,,5.0010958,,,,
,40191576.37,5.0003324,-3116.49694824219,1.75072869853417,0.00038042835286719,1,0.999253354069792,40.0298881530762,1.9887299005506,11.6100003942847,8.78850182611463,2.0008467144494,25,0.0357358701859413,1.64323798530603,0.0809264101199586,5.0003324,5.0003324,-3127.05688476562,-3105.93701171875,49.1581808314667,18.4255157811998,8.168791,0,0,0,40,4961,5.0062,-3116.49694824219,,,,,,,,,,,,,0,,,,0.5928041,,,,,,5.0003324,,,,
,40191627.985,4.9994202,-6731.28540039063,1.41349458027105,0.000347628431173334,1,0.999253354069792,40.0298881530762,1.98877454041168,11.6100003942847,7.10521152987345,1.622209272707,25,0.0277652896578978,1.32861979298808,0.0662501580490524,4.9994202,4.9994202,-6734.765625,-6727.80517578125,49.2582292819283,18.4244755633406,7.059639,0,0,0,40,4961,5.0066,-6731.28540039063,,,,,,,,,,,,,0,,,,0.5928041,,,,,,4.9994202,,,,
,40191679.185,5.0002604,-10314.9443359375,1.15890409361311,0.000226293657179207,1,0.999253354069792,40.0298881530762,1.98897311089818,11.6100003942847,5.83470839065611,1.33708625230192,25,0.0220622032404682,1.09109615292317,0.0552879534494065,5.0002604,5.0002604,-10325.48046875,-10304.408203125,49.2105499422552,18.4280536787904,7.059639,0,0,0,40,4961,5.0063,-10314.9443359375,,,,,,,,,,,,,0,,,,0.6047672,,,,,,5.0002604,,,,
,40191729.6,5.0002112,-13845.7490234375,0.997221565233444,0.00027931433935254,1,0.999253354069792,40.0298881530762,1.98866721083653,11.6100003942847,5.02772377781436,1.15806965345765,25,0.0187471156383648,0.940517889569059,0.0487112149317613,5.0000734,5.000349,-13859.7392578125,-13831.7587890625,49.7240798793899,18.429504193518,7.059639,0,0,0,40,4961,5.00635,-13845.7490234375,,,,,,,,,,,,,0,,,,0.6017615,,,,,,5.0002112,,,,
,40191779.985,5.000289,-17371.9287109375,0.888166972126671,0.000197063752042351,1,0.999253354069792,40.0298881530762,1.9889056766342,11.6200000047684,4.48616304959105,1.03721034115748,25,0.0162931354546037,0.839235037367226,0.0441569628133086,5.000289,5.000289,-17378.919921875,-17364.9375,49.3285758486591,18.4325542551189,8.168791,0,0,0,40,4961,5.00635,-17371.9287109375,,,,,,,,,,,,,0,,,,0.5869115,,,,,,5.000289,,,,
,40191832.735,4.99847295,-21063.216796875,0.802341723562532,0.000152812965893829,1,0.999253354069792,40.0298881530762,1.98883780621734,11.6100003942847,4.06046788257406,0.941345355073785,25,0.014214498051921,0.759705809630008,0.040427752130188,4.9983511,4.9985948,-21073.76953125,-21052.6640625,49.6341925996783,18.4307714898692,8.168791,0,0,0,40,4961,5.0077,-21063.216796875,,,,,,,,,,,,,0,,,,0.5987558,,,,,,4.99847295,,,,
,40191883.74,4.9993687,-24632.4384765625,0.737926502178767,0.000112939394663553,1,0.999253354069792,40.0298881530762,1.98890793056111,11.6200000047684,3.74164532354972,0.871145831932068,25,0.0129850567277048,0.700148404429617,0.0379196297166258,4.9992824,4.999455,-24635.927734375,-24628.94921875,50.0046845177938,18.428480239257,7.429356,0,0,0,40,4961,5.0088,-24632.4384765625,,,,,,,,,,,,,0,,,,0.5869115,,,,,,4.9993687,,,,
,40191935.93,4.9984512,-28285.7275390625,0.684810810974747,0.000115899885139498,1,0.999253354069792,40.0298881530762,1.98878303116331,11.6100003942847,3.47902180704148,0.813241829693177,25,0.0120049649594118,0.65114815462011,0.0358428316022297,4.9984512,4.9984512,-28289.255859375,-28282.19921875,49.3567144753514,18.4311417140361,7.429356,0,0,0,40,4961,5.00945,-28285.7275390625,,,,,,,,,,,,,0,,,,0.5987558,,,,,,4.9984512,,,,
,40191987.635,4.9978461,-31902.8466796875,0.641019123365309,8.79074197473479E-5,1,0.999253354069792,40.0298881530762,1.98876309697864,11.6100003942847,3.26318104899801,0.764950711988901,25,0.0111271462006906,0.610825074707135,0.0340082396804604,4.9978461,4.9978461,-31913.419921875,-31892.2734375,49.5388339203322,18.4286361593265,8.168791,0,0,0,40,4961,5.0101,-31902.8466796875,,,,,,,,,,,,,0,,,,0.5869115,,,,,,4.9978461,,,,
,40192040.215,4.9972262,-35583.4609375,0.603239422445601,9.30048303363234E-5,1,0.999253354069792,40.0298881530762,1.98896020836338,11.6100003942847,3.07752604620824,0.723672270087232,25,0.0104832674799624,0.576088282439236,0.0324733450856655,4.9971499,4.9973025,-35593.86328125,-35573.05859375,49.1956990003898,18.431163772015,8.168791,0,0,0,40,4961,5.01135,-35583.4609375,,,,,,,,,,,,,0,,,,0.58991665,,,,,,4.9972262,,,,
,40192094.68,4.997683,-39393.666015625,0.570071290764519,0.000105346381671311,1,0.999253354069792,40.0298881530762,1.98870926826081,11.6100003942847,2.91417268391248,0.687358911738112,25,0.00998467223758075,0.545643568237145,0.0311307311857524,4.997683,4.997683,-39400.625,-39386.70703125,49.1683420022167,18.4278931103888,8.168791,0,0,0,40,4961,5.01255,-39393.666015625,,,,,,,,,,,,,0,,,,0.5810775,,,,,,4.997683,,,,
,40192146.965,4.9967604,-43053.953125,0.542391361640175,7.52010273378157E-5,1,0.999253354069792,40.0298881530762,1.98850602226421,11.6200000047684,2.77805525817164,0.656933177332199,25,0.0095999297302364,0.520262392024005,0.0299816267556699,4.9967604,4.9967604,-43061.04296875,-43046.86328125,49.9054176958514,18.4281481869811,8.168791,0,0,0,40,4961,5.0148,-43053.953125,,,,,,,,,,,,,0,,,,0.5869408,,,,,,4.9967604,,,,
,40192198.745,4.9962816,-46679.375,0.518091980795902,8.99596720325625E-5,1,0.999253354069792,40.0298881530762,1.98882395022243,11.6100003942847,2.65934917852783,0.630030339204781,25,0.00925004514496446,0.497990975093049,0.0289059574242418,4.9962816,4.9962816,-46693.265625,-46665.484375,48.393748139659,18.4317787409959,8.168791,0,0,0,40,4961,5.01695,-46679.375,,,,,,,,,,,,,0,,,,0.5753015,,,,,,4.9962816,,,,
,40192251.26,4.99641205,-50353.216796875,0.496019213475523,8.11342732978835E-5,1,0.999253354069792,40.0298881530762,1.98896759184651,11.6100003942847,2.55130030330778,0.605478653099808,25,0.00897500017830687,0.477757206967598,0.0279176212087811,4.9962921,4.996532,-50367.140625,-50339.29296875,50.3493826947746,18.4272397491297,7.429356,0,0,0,40,4961,5.0191,-50353.216796875,,,,,,,,,,,,,0,,,,0.5928041,,,,,,4.99641205,,,,
,40192303.085,4.9958186,-53980.830078125,0.476352557847498,7.12774284400735E-5,1,0.999253354069792,40.0298881530762,1.98880153273274,11.6100003942847,2.45457455378148,0.583691082552541,25,0.00881395039550207,0.459718792809743,0.0270712510680506,4.9958186,4.9958186,-53991.2421875,-53970.41796875,49.900727924736,18.4278092704957,8.168791,0,0,0,40,4961,5.0212,-53980.830078125,,,,,,,,,,,,,0,,,,0.5811065,,,,,,4.9958186,,,,
,40192355.485,4.9930563,-57647.630859375,0.458668032937549,7.42588677739074E-5,1,0.999253354069792,40.0298881530762,1.98878018464204,11.6200000047684,2.36786351331236,0.563793919571949,25,0.00864400419588713,0.443506186945204,0.0262450645126799,4.9930563,4.9930563,-57658.10546875,-57637.15625,49.5740072036975,18.4313084157761,8.168791,0,0,0,40,4961,5.0212,-57647.630859375,,,,,,,,,,,,,0,,,,0.5869115,,,,,,4.9930563,,,,
,40192408.685,4.9907548,-61370.58203125,0.442190885060955,6.72717801305621E-5,1,0.999253354069792,40.0298881530762,1.98864036523069,11.6100003942847,2.28678412786975,0.545398651345223,25,0.00856325813670675,0.428378080146416,0.0255117020481598,4.989603,4.9919066,-61381.09375,-61360.0703125,49.6341925996783,18.43138744634,7.429356,0,0,0,40,4961,5.0226,-61370.58203125,,,,,,,,,,,,,0,,,,0.57533025,,,,,,4.9907548,,,,
,40192460.935,4.9917102,-65039.595703125,0.42714805996024,6.61549891980965E-5,1,0.999253354069792,40.0298881530762,1.98863267700597,11.6100003942847,2.21278724348424,0.528487836874094,25,0.00849965028770278,0.414541365976787,0.02481884414566,4.9917102,4.9917102,-65046.640625,-65032.55078125,49.1863194581591,18.4305489472541,8.168791,0,0,0,40,4961,5.02905,-65039.595703125,,,,,,,,,,,,,0,,,,0.5639212,,,,,,4.9917102,,,,
,40192511.38,4.7878189,-68592.51953125,0.417114435710749,8.40675514949799E-5,1,0.999253354069792,40.0298881530762,1.98860150092604,11.6100003942847,2.16426162403656,0.517394739716934,25,0.00850495007091022,0.40547257334014,0.0243641921639378,4.7318015,4.8438363,-68602.9921875,-68582.046875,50.0805024841591,18.4307107128234,8.168791,0,0,0,40,4966,5.0159,-68592.51953125,,,,,,,,,,,,,0,,,,0.5639494,,,,,,4.7878189,,,,
,40192568.15,5.0135722,-72595.61328125,0.39981710658975,5.90087618588397E-5,1,0.999253354069792,40.0298881530762,1.98857901076998,11.6100003942847,2.07822040021592,0.496663463753323,25,0.00827213345694348,0.38935198139557,0.0233667166012562,5.0135722,5.0135722,-72609.7421875,-72581.484375,50.7949109507361,18.4325685247884,8.168791,0,0,0,40,4965,5.0242,-72595.61328125,,,,,,,,,,,,,0,,,,0.5583158,,,,,,5.0135722,,,,
,40192623.055,5.0020642,-76458.734375,0.38760138032145,5.46880772316442E-5,1,0.999253354069792,40.0298881530762,1.98875411560949,11.6100003942847,2.01800318864911,0.483155529817091,25,0.00834100485564727,0.378065888292554,0.0228464434173742,5.0020642,5.0020642,-76469.25,-76448.21875,50.259495415063,18.431987695181,7.429356,0,0,0,40,4965,5.02405,-76458.734375,,,,,,,,,,,,,0,,,,0.56961135,,,,,,5.0020642,,,,
,40192694.335,4.9897408,-79798.44140625,0.253550828136717,0.00168196960888561,1,0.999253354069792,40.0298881530762,1.98881397624583,11.6100003942847,1.32206029342639,0.315724717170167,25,0.00541035634201168,0.247650556099031,0.0148220742004917,4.9897408,4.9897408,-79808.609375,-79788.2734375,49.9593500636784,18.434956968086,7.429356,0,0,0,40,4965,5.0368,-79798.44140625,,,,,,,,,,,,,0,,,,0.57533025,,,,,,4.9897408,,,,
,40192752.535,4.9945288,-75766.6953125,-0.399742907874198,4.66906211765714E-5,1,0.999253354069792,40.0298881530762,1.98890507370852,11.6200000047684,-2.08160059830864,-0.494382571999807,25,-0.00784404344959303,-0.389824919220022,-0.0228458145241468,4.9945288,4.9945288,-75780.59375,-75752.796875,50.8324291196592,18.4374975994924,7.059639,0,0,0,40,4961,5.0369,-75766.6953125,,,,,,,,,,,,,0,,,,0.569583,,,,,,4.9945288,,,,
,40192805.235,4.9978409,-72099.5390625,-0.413161016871294,4.35095480645515E-5,1,0.999253354069792,40.0298881530762,1.98885263187146,11.6100003942847,-2.14796984522349,-0.510604154797683,25,-0.00803090957844119,-0.402278902208425,-0.023657299825812,4.9978409,4.9978409,-72109.9609375,-72089.1171875,50.1000431971399,18.4421951629888,8.538507,0,0,0,40,4961,5.03695,-72099.5390625,,,,,,,,,,,,,0,,,,0.569583,,,,,,4.9978409,,,,
,40192856.04,4.9989405,-68568.25,-0.425531482964044,4.08376158710502E-5,1,0.999253354069792,40.0298881530762,1.98876035319925,11.6100003942847,-2.20883819821007,-0.524396973260403,25,-0.0080092360703264,-0.413675803022682,-0.0242071924051465,4.9989405,4.9989405,-68571.8203125,-68564.6796875,50.218850732063,18.4370557621477,7.059639,0,0,0,40,4961,5.03475,-68568.25,,,,,,,,,,,,,0,,,,0.57533025,,,,,,4.9989405,,,,
,40192906.155,5.0000052,-65085.18359375,-0.438455118198569,3.37972699155164E-5,1,0.999253354069792,40.0298881530762,1.9888987586473,11.6100003942847,-2.27234910255315,-0.539617884183885,25,-0.00816061905870357,-0.425545891266288,-0.0249272144773307,5.0000052,5.0000052,-65095.53515625,-65074.83203125,49.5443053199668,18.4369410451052,7.059639,0,0,0,40,4961,5.03305,-65085.18359375,,,,,,,,,,,,,0,,,,0.5667521,,,,,,5.0000052,,,,
,40192957.91,5.0025458,-61483.380859375,-0.45289141406613,5.44422798390202E-5,1,0.999253354069792,40.0298881530762,1.98853903140797,11.6100003942847,-2.34271584844721,-0.555946064138873,25,-0.00826194591517048,-0.43878889463406,-0.025635003391818,5.0025458,5.0025458,-61493.796875,-61472.96484375,49.6271579430052,18.4359882895482,8.168791,0,0,0,40,4961,5.03215,-61483.380859375,,,,,,,,,,,,,0,,,,0.5667521,,,,,,5.0025458,,,,
,40193009.725,5.0034976,-57881.548828125,-0.468915441873145,7.29773645334415E-5,1,0.999253354069792,40.0298881530762,1.9887251247764,11.6200000047684,-2.42157897038376,-0.573763428223007,25,-0.00832303675992865,-0.453490018612846,-0.0263342048495435,5.0034976,5.0034976,-57885.04296875,-57878.0546875,49.3692205316591,18.4330987020202,8.168791,0,0,0,40,4961,5.0297,-57881.548828125,,,,,,,,,,,,,0,,,,0.5810775,,,,,,5.0034976,,,,
,40193060.26,5.0034919,-54367.16015625,-0.485515640906975,5.8481635509686E-5,1,0.999253354069792,40.0298881530762,1.98884042118354,11.6100003942847,-2.50278786133437,-0.593085261381792,25,-0.00860372543986294,-0.468674075359741,-0.0272302447446585,5.0034919,5.0034919,-54374.078125,-54360.2421875,49.3465533046014,18.4359284016186,8.538507,0,0,0,40,4961,5.0275,-54367.16015625,,,,,,,,,,,,,0,,,,0.5639212,,,,,,5.0034919,,,,
,40193111.625,5.0044861,-50797.890625,-0.504616945853114,6.78491041156293E-5,1,0.999253354069792,40.0298881530762,1.98879919904585,11.5999998524785,-2.59627547137177,-0.614583285490584,25,-0.00883645660877342,-0.486169677376636,-0.0281300927622029,5.0044861,5.0044861,-50808.27734375,-50787.50390625,50.0328231444861,18.4342771134079,7.429356,0,0,0,40,4961,5.02505,-50797.890625,,,,,,,,,,,,,0,,,,0.56680865,,,,,,5.0044861,,,,
,40193162.015,5.0040216,-47293.685546875,-0.525129968037106,7.92733923361005E-5,1,0.999253354069792,40.0298881530762,1.98862294362006,11.6100003942847,-2.69645175229353,-0.637390123259995,25,-0.00909468058984166,-0.504943257746763,-0.0290550299570215,5.0040216,5.0040216,-47297.02734375,-47290.34375,49.6857800819476,18.4424903401497,8.168791,0,0,0,40,4961,5.0231,-47293.685546875,,,,,,,,,,,,,0,,,,0.56961135,,,,,,5.0040216,,,,
,40193213.525,5.0044909,-43712.291015625,-0.548853863530321,8.66299569584294E-5,1,0.999253354069792,40.0298881530762,1.9884782329108,11.6100003942847,-2.81245917232857,-0.663814171306943,25,-0.00945144094311836,-0.526672798290521,-0.0301277932238824,5.0044909,5.0044909,-43715.75,-43708.83203125,49.9022911817745,18.4399431945906,7.429356,0,0,0,40,4961,5.0233,-43712.291015625,,,,,,,,,,,,,0,,,,0.5753015,,,,,,5.0044909,,,,
,40193265.365,5.0043292,-40103.751953125,-0.575696446670291,9.40668558216631E-5,1,0.999253354069792,40.0298881530762,1.98858178020617,11.6100003942847,-2.94414318578232,-0.69367746908732,25,-0.00989487119120923,-0.551265861526839,-0.031317940936756,5.0043292,5.0043292,-40114.12890625,-40093.375,49.6310660856014,18.4486609069814,8.168791,0,0,0,40,4961,5.0204,-40103.751953125,,,,,,,,,,,,,0,,,,0.5639212,,,,,,5.0043292,,,,
,40193317.435,5.003437,-36484.984375,-0.606711217463689,0.000100502564725429,1,0.999253354069792,40.0298881530762,1.98870675543822,11.6100003942847,-3.09670456462358,-0.727351650458143,25,-0.0103028307981361,-0.579724097114255,-0.0325305056480866,5.003437,5.003437,-36498.8828125,-36471.0859375,49.9077625814091,18.4404378733591,8.168791,0,0,0,40,4961,5.01805,-36484.984375,,,,,,,,,,,,,0,,,,0.5753015,,,,,,5.003437,,,,
,40193370.665,5.0034094,-32787.017578125,-0.643211836545971,8.51324319270556E-5,1,0.999253354069792,40.0298881530762,1.98863534307493,11.6200000047684,-3.27590375499609,-0.767855177683187,25,-0.0110385631672984,-0.613242565540325,-0.0341289563573626,5.0034094,5.0034094,-32793.9453125,-32780.08984375,49.7373675642168,18.4418136407239,8.168791,0,0,0,40,4961,5.01635,-32787.017578125,,,,,,,,,,,,,0,,,,0.5639212,,,,,,5.0034094,,,,
,40193423.99,5.0027976,-29066.2763671875,-0.686518755073988,0.000101990271573157,1,0.999253354069792,40.0298881530762,1.98859090523518,11.6100003942847,-3.48901707065529,-0.815529166557846,25,-0.0118990104410429,-0.653078913482943,-0.0359403678535868,5.0027976,5.0027976,-29073.265625,-29059.287109375,48.9995102420629,18.4433810994858,7.429356,0,0,0,40,4961,5.01555,-29066.2763671875,,,,,,,,,,,,,0,,,,0.569583,,,,,,5.0027976,,,,
,40193474.985,5.0023475,-25511.517578125,-0.736623975056507,0.000115751146752346,1,0.999253354069792,40.0298881530762,1.98853531341195,11.6200000047684,-3.7357545364145,-0.872466006714619,25,-0.0132877899255795,-0.699259293741852,-0.0383507440525811,5.0023475,5.0023475,-25521.984375,-25501.05078125,49.4809934099091,18.4418351664404,8.168791,0,0,0,40,4961,5.0148,-25511.517578125,,,,,,,,,,,,,0,,,,0.5639494,,,,,,5.0023475,,,,
,40193525.74,5.0025358,-21968.0703125,-0.798752735361238,0.000142599969659995,1,0.999253354069792,40.0298881530762,1.98839724604214,11.6200000047684,-4.04299257415032,-0.940018239101682,25,-0.0144371767428202,-0.75668616644745,-0.0407522350582736,5.0025358,5.0025358,-21971.53515625,-21964.60546875,49.5138218077168,18.4415776603522,8.168791,0,0,0,40,4961,5.014,-21968.0703125,,,,,,,,,,,,,0,,,,0.569583,,,,,,5.0025358,,,,
,40193576.72,5.0017557,-18414.28125,-0.87766255145781,0.000176453046015133,1,0.999253354069792,40.0298881530762,1.98865969835106,11.6100003942847,-4.43445477735805,-1.02865731429006,25,-0.0164249721112363,-0.829769896784898,-0.044264824707961,5.0017061,5.0018053,-18428.283203125,-18400.279296875,49.1753766588898,18.442463048113,8.168791,0,0,0,40,4961,5.01305,-18414.28125,,,,,,,,,,,,,0,,,,0.55279365,,,,,,5.0017557,,,,
,40193628.88,5.0012536,-14775.6215820313,-0.98631152088001,0.000190818132128769,1,0.999253354069792,40.0298881530762,1.98849302186031,11.6100003942847,-4.97426056776218,-1.1481168804511,25,-0.0186462116488231,-0.930671173872878,-0.0486219446344187,5.0012536,5.0012536,-14779.12109375,-14772.1220703125,49.5403971773706,18.4339229097092,8.168791,0,0,0,40,4961,5.0122,-14775.6215820313,,,,,,,,,,,,,0,,,,0.5583158,,,,,,5.0012536,,,,
,40193680.855,5.0008464,-11145.8203125,-1.14374207577882,0.000303776881225826,1,0.999253354069792,40.0298881530762,1.98856322932103,11.6100003942847,-5.7582527151419,-1.3261258711501,25,-0.0226411531192301,-1.07722351790044,-0.0557537937177034,5.0008464,5.0008464,-11152.8857421875,-11138.7548828125,49.9147972380822,18.4420865155337,8.168791,0,0,0,40,4961,5.0122,-11145.8203125,,,,,,,,,,,,,0,,,,0.54729885,,,,,,5.0008464,,,,
,40193733.27,5.00067,-7476.45532226563,-1.39392866060071,0.000341836439399054,1,0.999253354069792,40.0298881530762,1.98863410548481,11.6200000047684,-7.00737468901676,-1.60647651640613,25,-0.0282204712485459,-1.31062483083737,-0.0665296854698339,5.00067,5.00067,-7490.44677734375,-7462.4638671875,49.3035637360437,18.4463748063926,8.168791,0,0,0,40,4961,5.01245,-7476.45532226563,,,,,,,,,,,,,0,,,,0.5500188,,,,,,5.00067,,,,
,40193784.03,5.0007763,-3927.01867675781,-1.69822684837561,0.000506719278344715,1,0.999253354069792,40.0298881530762,1.98857785976498,11.6200000047684,-8.52421517455247,-1.95426379835232,25,-0.0367286059566872,-1.5943725928259,-0.0809410445799596,5.0007763,5.0007763,-3930.51245117188,-3923.52490234375,49.3997040439091,18.4362054994149,7.059639,0,0,0,40,4961,5.0129,-3927.01867675781,,,,,,,,,,,,,0,,,,0.5364457,,,,,,5.0007763,,,,
,40193836,5.0016932,-291.17106628418,-1.90505903036054,0.000328079940683945,1,0.999253354069792,40.0298881530762,1.98857182970573,11.6100003942847,-9.55241051436003,-2.18318855369561,25,-0.0422183821270116,-1.78647627207538,-0.0894821102712109,5.0016932,5.0016932,-298.178802490234,-284.163330078125,50.218850732063,18.4375088881564,8.168791,0,0,0,40,4961,5.0129,-291.17106628418,,,,,,,,,,,,,0,,,,0.5391924,,,,,,5.0016932,,,,
,40193959.22,4.9974194,3075.22521972656,-1.75871197775237,0.000419478590250456,1,0.999253354069792,40.0298881530762,1.98856578081896,11.6100003942847,-8.82550700600382,-2.02057380433175,25,-0.038066848630141,-1.65064844290649,-0.0833055089808603,4.9974194,4.9974194,3057.72021484375,3092.73022460937,49.6529516841399,18.4383544694903,8.168791,0,0,0,40,4961,5.01055,3075.22521972656,,,,,,,,,,,,,0,,,,0.53113985,,,,,,4.9974194,,,,
,40194012.33,4.99722885,6794.62646484375,-1.40944994651168,0.000387997184236218,1,0.999253354069792,40.0298881530762,1.98841297368465,11.6100003942847,-7.08158247407869,-1.62809276236696,25,-0.0297843687664543,-1.32479405360493,-0.0680692013086237,4.9969692,4.9974885,6784.14501953125,6805.10791015625,49.6615495978514,18.4377241683771,8.168791,0,0,0,40,4961,5.0122,6794.62646484375,,,,,,,,,,,,,0,,,,0.52586025,,,,,,4.99722885,,,,
,40194065.29,5.0021205,10500.7275390625,-1.14847093504233,0.000275201043627441,1,0.999253354069792,40.0298881530762,1.98834630396327,11.6100003942847,-5.77868679422812,-1.33546108596753,25,-0.0238973526522268,-1.08130814975834,-0.0567898890130073,5.0021205,5.0021205,10486.6728515625,10514.7822265625,49.7162635941976,18.4358824782649,8.168791,0,0,0,40,4961,5.0137,10500.7275390625,,,,,,,,,,,,,0,,,,0.52586025,,,,,,5.0021205,,,,
,40194116.695,4.9786062,14101.08203125,-0.990924020442205,0.000232331605418423,1,0.999253354069792,40.0298881530762,1.98844330256726,11.6100003942847,-4.99445412311956,-1.15856672924437,25,-0.0200717054963349,-0.934655762489729,-0.0498612608764315,4.9786062,4.9786062,14097.57421875,14104.58984375,49.3512430757168,18.4384665603658,7.429356,0,0,0,40,4965,4.9704,14101.08203125,,,,,,,,,,,,,0,,,,0.5180714,,,,,,4.9786062,,,,
,40194174,5.0135221,18110.388671875,-0.868785907142818,0.000143158473291821,1,0.999253354069792,40.0298881530762,1.98849888930763,11.6100003942847,-4.38781132630929,-1.02130517801321,25,-0.0170005217518455,-0.821216812678912,-0.0444260949282944,5.0135221,5.0135221,18099.89453125,18120.8828125,49.7967713316783,18.4393392188713,8.168791,0,0,0,40,4965,5.00165,18110.388671875,,,,,,,,,,,,,0,,,,0.5206331,,,,,,5.0135221,,,,
,40194227.45,4.9962616,21850.255859375,-0.787589841307326,0.000167803714429386,1,0.999253354069792,40.0298881530762,1.98850946159036,11.6100003942847,-3.98525610268862,-0.932400738058837,25,-0.0153525937511239,-0.746023321630636,-0.0412119260693899,4.9962616,4.9962616,21843.294921875,21857.216796875,48.7306300314475,18.4436405007303,8.168791,0,0,0,40,4965,5.0011,21850.255859375,,,,,,,,,,,,,0,,,,0.5364457,,,,,,4.9962616,,,,
,40194274.735,4.9976768,25160.2890625,-0.729610258270939,0.000121882148855301,1,0.999253354069792,40.0298881530762,1.98850557857193,11.6100003942847,-3.69868670734383,-0.86710316657667,25,-0.0138472562541772,-0.692435520738862,-0.0385629721482613,4.9976768,4.9976768,25153.216796875,25167.361328125,50.1305267093899,18.4313910066056,8.168791,0,0,0,40,4965,5.006,25160.2890625,,,,,,,,,,,,,0,,,,0.5364457,,,,,,4.9976768,,,,
,40194325.175,4.9973879,28691.2607421875,-0.679948726137171,8.26881530981774E-5,1,0.999253354069792,40.0298881530762,1.98861896235194,11.6100003942847,-3.45380892310706,-0.812594314240961,25,-0.0128332516137682,-0.646647642764449,-0.0365290121599856,4.9973879,4.9973879,28680.78515625,28701.736328125,49.2637006815629,18.4415057798774,7.059639,0,0,0,40,4961,5.00745,28691.2607421875,,,,,,,,,,,,,0,,,,0.52847365,,,,,,4.9973879,,,,
,40194377.265,4.9976196,32333.802734375,-0.636797065340628,0.00011920569594254,1,0.999253354069792,40.0298881530762,1.98853541989722,11.6100003942847,-3.24102598793546,-0.765315835091451,25,-0.0120343088658567,-0.606922029472446,-0.0347804153890158,4.9976196,4.9976196,32319.8046875,32347.80078125,49.7350226786591,18.4400093075748,8.168791,0,0,0,40,4961,5.00835,32333.802734375,,,,,,,,,,,,,0,,,,0.5338328,,,,,,4.9976196,,,,
,40194427.62,4.9973397,35860.4140625,-0.60091467701136,7.70550379065765E-5,1,0.999253354069792,40.0298881530762,1.98857260063056,11.6100003942847,-3.06453785428805,-0.725736905898556,25,-0.0113670818974249,-0.573928461474979,-0.0332626444363294,4.9973397,4.9973397,35846.296875,35874.53125,50.2884156702746,18.4355663012933,7.059639,0,0,0,40,4961,5.0099,35860.4140625,,,,,,,,,,,,,0,,,,0.5311133,,,,,,4.9973397,,,,
,40194479.625,4.9975591,39498.33203125,-0.56938266531898,8.80162602550413E-5,1,0.999253354069792,40.0298881530762,1.98852015326314,11.6100003942847,-2.90962668018716,-0.690817377309867,25,-0.0108051259226837,-0.544986651279926,-0.0318995572652455,4.9975591,4.9975591,39491.40234375,39505.26171875,49.2980923364091,18.4402537374524,7.429356,0,0,0,40,4961,5.0119,39498.33203125,,,,,,,,,,,,,0,,,,0.5418586,,,,,,4.9975591,,,,
,40194534.5,4.9953699,43340.111328125,-0.540336874484534,8.57978341430719E-5,1,0.999253354069792,40.0298881530762,1.98853299407338,11.6200000047684,-2.76708400320983,-0.658916841327819,25,-0.0103966753659534,-0.518346095372715,-0.0306858364475553,4.9953699,4.9953699,43333.1015625,43347.12109375,49.1933541148321,18.4416021898644,8.168791,0,0,0,40,4961,5.0143,43340.111328125,,,,,,,,,,,,,0,,,,0.5472715,,,,,,4.9953699,,,,
,40194587.58,4.9952874,47052.638671875,-0.515619225095596,6.82210432796584E-5,1,0.999253354069792,40.0298881530762,1.98836809488248,11.6100003942847,-2.64554414489047,-0.631991571267012,25,-0.0101608550593602,-0.495682624276971,-0.0297029465029794,4.9952874,4.9952874,47049.078125,47056.19921875,49.3059086216014,18.4376139750804,8.168791,0,0,0,40,4961,5.0156,47052.638671875,,,,,,,,,,,,,0,,,,0.5472715,,,,,,4.9952874,,,,
,40194702.76,4.9971061,49672.9375,-0.281726005540547,0.00168820476886297,1,0.999253354069792,40.0298881530762,1.98852305659771,11.6100003942847,-1.44793785303659,-0.344920440409812,25,-0.00534124340374098,-0.271241420415751,-0.0160800669982867,4.9971061,4.9971061,49662.66796875,49683.20703125,49.6732740256399,18.4404503284234,7.429356,0,0,0,40,4961,5.021,49672.9375,,,,,,,,,,,,,0,,,,0.5418316,,,,,,4.9971061,,,,
,40194760.57,4.99963425,45662.228515625,0.523633642077074,0.000107854734412325,1,0.999253354069792,40.0298881530762,1.98825905552745,11.6100003942847,2.68530712461791,0.637012419726029,25,0.00953484361137454,0.50301768304999,0.0293458537080631,4.9995813,4.9996872,45655.25,45669.20703125,49.5403971773706,18.4432858239486,7.059639,0,0,0,40,4961,5.0209,45662.228515625,,,,,,,,,,,,,0,,,,0.5338328,,,,,,4.99963425,,,,
,40194814.235,4.9998918,41932.787109375,0.561705597200608,0.000132490354354272,1,0.999253354069792,40.0298881530762,1.98858423204023,11.6100003942847,2.87493043334538,0.681124406844572,25,0.0102383510254732,0.53842479375192,0.0312565729210582,4.9998918,4.9998918,41922.39453125,41943.1796875,49.8186569302168,18.4432279810067,8.168791,0,0,0,40,4961,5.0191,41932.787109375,,,,,,,,,,,,,0,,,,0.5206072,,,,,,4.9998918,,,,
,40194865.875,5.0005014,38342.271484375,0.589948169083423,0.000120373824695466,1,0.999253354069792,40.0298881530762,1.98843288253483,11.6100003942847,3.01324679560297,0.711859430262432,25,0.0106230199055322,0.564306429958597,0.0323969976940902,5.0004568,5.000546,38335.390625,38349.15234375,49.6013642018706,18.4470993918646,8.168791,0,0,0,40,4961,5.0183,38342.271484375,,,,,,,,,,,,,0,,,,0.5311133,,,,,,5.0005014,,,,
,40194917.98,5.0009246,34719.865234375,0.623597092957782,0.000103965940750106,1,0.999253354069792,40.0298881530762,1.98831691997607,11.6100003942847,3.17828346124095,0.74950400710003,25,0.0113249633300403,0.595204937302791,0.0339316562731842,5.0009246,5.0009246,34705.89453125,34733.8359375,49.4122101002168,18.446298415995,7.429356,0,0,0,40,4961,5.0169,34719.865234375,,,,,,,,,,,,,0,,,,0.5206331,,,,,,5.0009246,,,,
,40194970.155,5.0016313,31092.16015625,0.662655049272817,0.000108748262182205,1,0.999253354069792,40.0298881530762,1.98831490918918,11.6100003942847,3.37053785046975,0.792016770046301,25,0.01196758309736,0.631119903359729,0.035476352772833,5.0016313,5.0016313,31081.765625,31102.5546875,49.6881249675053,18.444246417212,7.059639,0,0,0,40,4961,5.0166,31092.16015625,,,,,,,,,,,,,0,,,,0.5180714,,,,,,5.0016313,,,,
,40195022.29,5.0012822,27451.4658203125,0.708860857602988,0.000114803615770276,1,0.999253354069792,40.0298881530762,1.98830784298964,11.6100003942847,3.59818690096583,0.842926537824765,25,0.0129132943736881,0.673666662934835,0.0374080522358753,5.0012822,5.0012822,27440.93359375,27461.998046875,48.9268187897744,18.4446022129581,8.168791,0,0,0,40,4961,5.0158,27451.4658203125,,,,,,,,,,,,,0,,,,0.50777255,,,,,,5.0012822,,,,
,40195074.01,5.0018969,23845.1455078125,0.765383609477249,0.000118777309848875,1,0.999253354069792,40.0298881530762,1.98839781268131,11.6100003942847,3.87747045217624,0.905823100354669,25,0.0142108601767869,0.725842931093694,0.0398550245006144,5.0018969,5.0018969,23834.6484375,23855.642578125,49.8983830391784,18.4480756010652,8.168791,0,0,0,40,4961,5.0157,23845.1455078125,,,,,,,,,,,,,0,,,,0.5078232,,,,,,5.0018969,,,,
,40195127.815,5.0013599,20095.8515625,0.837752502036047,0.000159122972521626,1,0.999253354069792,40.0298881530762,1.98847733561328,11.6100003942847,4.23544778835497,0.987456933137293,25,0.0161419928047626,0.792760297914936,0.0431743747660897,5.0013599,5.0013599,20088.822265625,20102.880859375,49.5865132600052,18.4481386191372,7.429356,0,0,0,40,4961,5.0138,20095.8515625,,,,,,,,,,,,,0,,,,0.5002142,,,,,,5.0013599,,,,
,40195178.61,5.00180485,16548.8896484375,0.928917365151958,0.000185188883033637,1,0.999253354069792,40.0298881530762,1.9883689241219,11.6200000047684,4.68742874427537,1.089727019029,25,0.0184353748529753,0.877306978263807,0.0472259371881372,5.0018034,5.0018063,16538.375,16559.404296875,48.9401064746013,18.4464051162551,8.168791,0,0,0,40,4961,5.0135,16548.8896484375,,,,,,,,,,,,,0,,,,0.5052363,,,,,,5.00180485,,,,
,40195231.89,5.001081,12829.6586914062,1.06484447857127,0.00021099084434324,1,0.999253354069792,40.0298881530762,1.98846598424494,11.6100003942847,5.36383487895787,1.24279963895382,25,0.0218052515178278,1.00372395666589,0.0532871702536757,5.001081,5.001081,12822.7939453125,12836.5234375,49.6623312263706,18.4498282971312,7.059639,0,0,0,40,4961,5.0129,12829.6586914062,,,,,,,,,,,,,0,,,,0.4903192,,,,,,5.001081,,,,
,40195284.615,5.0001426,9144.61865234375,1.2671210855568,0.000284783091196758,1,0.999253354069792,40.0298881530762,1.98841201885876,11.6100003942847,6.37234549019612,1.46968544020753,25,0.0264799024230809,1.19226090236775,0.0620879261101151,5.0001426,5.0001426,9134.11328125,9155.1240234375,48.688422091409,18.4473379493496,8.168791,0,0,0,40,4961,5.0132,9144.61865234375,,,,,,,,,,,,,0,,,,0.4952419,,,,,,5.0001426,,,,
,40195336.565,4.9998283,5513.07861328125,1.5553548121662,0.00029678887739374,1,0.999253354069792,40.0298881530762,1.98858290327069,11.6100003942847,7.81119105567717,1.79509830407678,25,0.0335087274323969,1.46114113389194,0.0749438649725778,4.9998283,4.9998283,5506.07080078125,5520.08642578125,49.4497282691398,18.4410828441031,8.168791,0,0,0,40,4961,5.01355,5513.07861328125,,,,,,,,,,,,,0,,,,0.4854454,,,,,,4.9998283,,,,
,40195386.98,5.0010085,1987.32916259766,1.84479140598728,0.000356379961928654,1,0.999253354069792,40.0298881530762,1.98844270149868,11.6100003942847,9.25221503567924,2.12438818990559,25,0.0417971439844363,1.73075498793628,0.0884389637764401,5.0010085,5.0010085,1973.25708007813,2001.40124511719,50.1031697112168,18.4469380275019,7.059639,0,0,0,40,4961,5.0136,1987.32916259766,,,,,,,,,,,,,0,,,,0.4903192,,,,,,5.0010085,,,,
,40195415.525,5.0004005,-0.343940854072571,1.90706046693115,0.000468409577845702,1,0.999253354069792,40.0298881530762,1.98838438973923,11.6100003942847,9.5595148363636,2.19265753350865,25,0.0438603254388809,1.78821822368141,0.0909673693793139,5.0004005,5.0004005,-0.343940854072571,-0.343940854072571,49.6099621155822,18.4450053856267,7.059639,0,0,0,40,4929,5.0119,-0.343940854072571,,,,,,,,,,,,,0,,,,0.4758425,,,,,,5.0004005,,,,